Workbook

Sheet 2回目結果
A1: キットの管理Noを記載してください | B1: 性別 | C1: 生年月日 | D1: 年齢 | E1: 1. 非常にたくさんの仕事をしなければならない | F1: 2. 時間内に仕事が処理しきれない | G1: 3. 一生懸命働かなければならない | H1: 4. かなり注意を集中する必要がある | I1: 5. 高度の知識や技術が必要なむずかしい仕事だ | J1: 6. 勤務時間中はいつも仕事のことを考えていなければならない | K1: 7. からだを大変よく使う仕事だ | L1: 8. 自分のペースで仕事ができる | M1: 9. 自分の仕事の順番・やり方を決めることができる | N1: 10. 職場の仕事の方針に自分の意見を反映できる | O1: 11. 自分の技能や知識を仕事で使うことが少ない | P1: 12. 私の部署内で意見のくい違いがある | Q1: 13. 私の部署と他の部署とはうまが合わない | R1: 14. 私の職場の雰囲気は友好的である | S1: 15. 私の職場の作業環境（騒音、照明、温度、換気など）はよくない | T1: 16. 仕事の内容は自分にあってる | U1: 17. 働きがいのある仕事だ | V1: 心理的な仕事の負担（質） | W1: 心理的な仕事の負担（質） | X1: 心理的な仕事の負担（量） | Y1: 心理的な仕事の負担（量） | Z1: 自覚的な身体的負担度 | AA1: 自覚的な身体的負担度 | AB1: 職場の対人関係でのストレス | AC1: 職場の対人関係でのストレス | AD1: 職場環境によるストレス | AE1: 職場環境によるストレス | AF1: 仕事のコントロール度 | AG1: 仕事のコントロール度 | AH1: 技能の活用度 | AI1: 技能の活用度 | AJ1: 仕事の適性度 | AK1: 仕事の適性度 | AL1: 働きがい | AM1: 働きがい | AN1: 1. 活気がわいてくる | AO1: 2. 元気がいっぱいだ | AP1: 3. 生き生きする | AQ1: 4. 怒りを感じる | AR1: 5. 内心腹立だしい | AS1: 6. イライラしている | AT1: 7. ひどく疲れた | AU1: 8. へとへとだ | AV1: 9. だるい | AW1: 10. 気がはりつめている | AX1: 11. 不安だ | AY1: 12. 落ち着かない | AZ1: 13. ゆううつだ | BA1: 14. 何をするのも面倒だ | BB1: 15. 物事に集中できない | BC1: 16. 気分が晴れない | BD1: 17. 仕事が手につかない | BE1: 18. 悲しいと感じる | BF1: 19. めまいがする | BG1: 20. 体のふしぶしが痛む | BH1: 21. 頭が重かったり頭痛がする | BI1: 22. 首筋や肩がこる | BJ1: 23. 腰が痛い | BK1: 24. 目が疲れる | BL1: 25. 動悸や息切れがする | BM1: 26. 胃腸の具合が悪い | BN1: 27. 食欲がない | BO1: 28. 便秘や下痢をする | BP1: 29. よく眠れない | BQ1: 活気 | BR1: 活気 | BS1: イライラ感 | BT1: イライラ感 | BU1: 疲労感 | BV1: 疲労感 | BW1: 不安感 | BX1: 不安感 | BY1: 抑うつ感 | BZ1: 抑うつ感 | CA1: 身体愁訴 | CB1: 身体愁訴 | CC1: 次の人たちはどのくらい気軽に話ができますか？ 1．上司 | CD1: 次の人たちはどのくらい気軽に話ができますか？ 2. 職場の同僚 | CE1: 次の人たちはどのくらい気軽に話ができますか？ 3. 配偶者、家族、友人等 | CF1: あなたが困った時、次の人たちはどのくらい頼りになりますか？ 4. 上司 | CG1: あなたが困った時、次の人たちはどのくらい頼りになりますか？ 5. 職場の同僚 | CH1: あなたが困った時、次の人たちはどのくらい頼りになりますか？ 6. 配偶者、家族、友人等 | CI1: あなたの個人的な問題を相談したら、次の人たちはどのくらいきいてくれますか？ 7. 上司 | CJ1: あなたの個人的な問題を相談したら、次の人たちはどのくらいきいてくれますか？ 8. 職場の同僚 | CK1: あなたの個人的な問題を相談したら、次の人たちはどのくらいきいてくれますか？ 9. 配偶者、家族、友人等 | CL1: 1. 仕事に満足だ | CM1: 2. 家庭生活に満足だ | CN1: 上司からのサポート | CO1: 上司からのサポート | CP1: 同僚からのサポート | CQ1: 同僚からのサポート | CR1: 家族・友人からのサポート | CS1: 家族・友人からのサポート | CT1: 仕事や生活の満足度 | CU1: 仕事や生活の満足度 | CV1: 心身の反応 | CW1: ストレスの原因 | CX1: ストレスに影響を与えるその他因子 | CY1: ストレスチェック総合評価 | CZ1: 東大式 | DA1: プレゼンティーズム | DB1: 1. 寝床についてから実際に寝るまで、時間 がかかりましたか？ | DC1: 2.夜間、睡眠の途中で目が覚めましたか？ | DD1: 3. 希望する起床時間より早く目覚めて、それ 以降、眠れないことはありましたか？ | DE1: 4. 夜の眠りや昼寝も合わせて、睡眠時間は 足りていましたか？ | DF1: 5. 全体的な睡眠の質について、どう感じてい ますか？ | DG1: 6. 日中の気分はいかがでしたか？ | DH1: 7. 日中の身体的および精神的な活動の状 態は、いかがでしたか？ | DI1: 8. 日中の眠気はありましたか？ | DJ1: アテネ不眠スコア（点数） | DK1: アテネ不眠スコア（評価） | DL1: 8月時間外労働時間 | DM1: 9月時間外労働時間 | DN1: 10月時間外労働時間 | DO1: 8-10月時間外労働時間 | DP1: 直近3か月以内の部署異動 | DQ1: 昇格・降格 | DR1: 担当顧客変更の有無 | DS1: 睡眠時間 | DT1: 1回目キットNo | DU1: 1回目バイオピリン | DV1: 1回目クレアチニン | DW1: 1回目BP（CRE補正後） | DX1: 1回目スコア | DY1: 4月時間外労働時間 | DZ1: 5月時間外労働時間 | EA1: 6月時間外労働時間 | EB1: 4-6月時間外労働時間 | EC1: 直近3か月以内の部署異動 | ED1: 担当顧客変更の有無 | EE1: バイオピリン | EF1: クレアチニン | EG1: BP（CRE補正後） | EH1: スコア | EI1: アラート有無 | EJ1: 2回目/1回目スコア | EK1: 2回目/1回目 BP（CRE補正後） | EL1: 2回目/1回目時間外労働時間 | EM1: 2回目/1回目 直近1ヵ月時間外労働時間
A2: 300 | B2: male | C2: 29883 | D2: 42 | E2: =IF(('2回目フォームの回答 '!C2="そうだ"),1,(IF(('2回目フォームの回答 '!C2="まぁそうだ"),2,(IF(('2回目フォームの回答 '!C2="ややちがう"),3,(IF(('2回目フォームの回答 '!C2="ちがう"),4,""))))))) -> 2 | F2: =IF(('2回目フォームの回答 '!D2="そうだ"),1,(IF(('2回目フォームの回答 '!D2="まぁそうだ"),2,(IF(('2回目フォームの回答 '!D2="ややちがう"),3,(IF(('2回目フォームの回答 '!D2="ちがう"),4,""))))))) -> 2 | G2: =IF(('2回目フォームの回答 '!E2="そうだ"),1,(IF(('2回目フォームの回答 '!E2="まぁそうだ"),2,(IF(('2回目フォームの回答 '!E2="ややちがう"),3,(IF(('2回目フォームの回答 '!E2="ちがう"),4,""))))))) -> 1 | H2: =IF(('2回目フォームの回答 '!F2="そうだ"),1,(IF(('2回目フォームの回答 '!F2="まぁそうだ"),2,(IF(('2回目フォームの回答 '!F2="ややちがう"),3,(IF(('2回目フォームの回答 '!F2="ちがう"),4,""))))))) -> 2 | I2: =IF(('2回目フォームの回答 '!G2="そうだ"),1,(IF(('2回目フォームの回答 '!G2="まぁそうだ"),2,(IF(('2回目フォームの回答 '!G2="ややちがう"),3,(IF(('2回目フォームの回答 '!G2="ちがう"),4,""))))))) -> 2 | J2: =IF(('2回目フォームの回答 '!H2="そうだ"),1,(IF(('2回目フォームの回答 '!H2="まぁそうだ"),2,(IF(('2回目フォームの回答 '!H2="ややちがう"),3,(IF(('2回目フォームの回答 '!H2="ちがう"),4,""))))))) -> 2 | K2: =IF(('2回目フォームの回答 '!I2="そうだ"),1,(IF(('2回目フォームの回答 '!I2="まぁそうだ"),2,(IF(('2回目フォームの回答 '!I2="ややちがう"),3,(IF(('2回目フォームの回答 '!I2="ちがう"),4,""))))))) -> 4 | L2: =IF(('2回目フォームの回答 '!J2="そうだ"),1,(IF(('2回目フォームの回答 '!J2="まぁそうだ"),2,(IF(('2回目フォームの回答 '!J2="ややちがう"),3,(IF(('2回目フォームの回答 '!J2="ちがう"),4,""))))))) -> 2 | ... U2: =IF(('2回目フォームの回答 '!S2="そうだ"),1,(IF(('2回目フォームの回答 '!S2="まぁそうだ"),2,(IF(('2回目フォームの回答 '!S2="ややちがう"),3,(IF(('2回目フォームの回答 '!S2="ちがう"),4,""))))))) -> 3 | V2: =15-($E2+$F2+$G2) -> 10 | W2: =IF(AND(B2="male",V2<=5),1,(IF(AND(B2="male",V2>=6,V2<=7),2,(IF(AND(B2="male",V2>=8,V2<=9),3,(IF(AND(B2="male",V2>=10,V2<=11),4,IF(AND(B2="male",V2>=12),5,IF(AND(B2="female",V2<=4),1,(IF(AND(B2="female",V2>=5,V2<=6),2,(IF(AND(B2="female",V2>=7,V2<=9),3,(IF(AND(B2="female",V2>=10,V2<=11),4,IF(AND(B2="female",V2>=12),5,"")))))))))))))))) -> 4 | X2: =15-($H2+$I2+$J2) -> 9 | Y2: =IF(AND(B2="male",X2<=5),1,(IF(AND(B2="male",X2>=6,X2<=7),2,(IF(AND(B2="male",X2>=8,X2<=9),3,(IF(AND(B2="male",X2>=10,X2<=11),4,IF(AND(B2="male",X2>=12),5,IF(AND(B2="female",X2<=4),1,(IF(AND(B2="female",X2>=5,X2<=6),2,(IF(AND(B2="female",X2>=7,X2<=8),3,(IF(AND(B2="female",X2>=9,X2<=10),4,IF(AND(B2="female",X2>=11),5,"")))))))))))))))) -> 3 | Z2: =5-$K2 -> 1 | AA2: =IF(Z2=1,2,IF(Z2=2,3,(IF(Z2=3,4,(IF(Z2=4,5,"")))))) -> 2 | AB2: =10-($P2+Q2)+$R2 -> 5 | AC2: =IF((AB2=3),1,(IF(AND(AB2>=4,AB2<=5),2,(IF(AND(AB2>=6,AB2<=7),3,(IF(AND(AB2>=8,AB2<=9),4,IF(AB2>=10,5,"")))))))) -> 2 | AD2: =5-$S2 -> 2 | AE2: =IF(AND(B2="male",AD2=1),2,IF(AND(B2="male",AD2=2),3,(IF(AND(B2="male",AD2=3),4,(IF(AND(B2="male",AD2=4),5,IF(AND(B2="female",AD2=1),1,IF(AND(B2="female",AD2=2),3,(IF(AND(B2="female",AD2=3),4,(IF(AND(B2="female",AD2=4),5,"")))))))))))) -> 3 | AF2: =15-($L2+$M2+$N2) -> 9 | AG2: =IF(AND(B2="male",AF2<=4),5,(IF(AND(B2="male",AF2>=5,AF2<=6),4,(IF(AND(B2="male",AF2>=7,AF2<=8),3,(IF(AND(B2="male",AF2>=9,AF2<=10),2,IF(AND(B2="male",AF2>=11),1,IF(AND(B2="female",AF2<=3),5,(IF(AND(B2="female",AF2>=4,AF2<=5),4,(IF(AND(B2="female",AF2>=6,AF2<=8),3,(IF(AND(B2="female",AF2>=9,AF2<=10),2,IF(AND(B2="female",AF2>=11),1,"")))))))))))))))) -> 2 | AH2: =$O2 -> 2 | AI2: =IF(AH2=1,5,IF(AH2=2,4,(IF(AH2=3,3,(IF(AH2=4,2,"")))))) -> 4 | AJ2: =5-$T2 -> 2 | AK2: =IF(AJ2=1,5,IF(AJ2=2,4,(IF(AJ2=3,3,(IF(AJ2=4,1,"")))))) -> 4 | AL2: =5-$U2 -> 2 | AM2: =IF(AL2=1,5,IF(AL2=2,4,(IF(AL2=3,3,(IF(AL2=4,1,"")))))) -> 4 | AN2: =IF(('2回目フォームの回答 '!T2="ほとんどなかった"),1,(IF(('2回目フォームの回答 '!T2="ときどきあった"),2,(IF(('2回目フォームの回答 '!T2="しばしばあった"),3,(IF(('2回目フォームの回答 '!T2="ほとんどいつもあった"),4,""))))))) -> 1 | AO2: =IF(('2回目フォームの回答 '!U2="ほとんどなかった"),1,(IF(('2回目フォームの回答 '!U2="ときどきあった"),2,(IF(('2回目フォームの回答 '!U2="しばしばあった"),3,(IF(('2回目フォームの回答 '!U2="ほとんどいつもあった"),4,""))))))) -> 2 | AP2: =IF(('2回目フォームの回答 '!V2="ほとんどなかった"),1,(IF(('2回目フォームの回答 '!V2="ときどきあった"),2,(IF(('2回目フォームの回答 '!V2="しばしばあった"),3,(IF(('2回目フォームの回答 '!V2="ほとんどいつもあった"),4,""))))))) -> 1 | AQ2: =IF(('2回目フォームの回答 '!W2="ほとんどなかった"),1,(IF(('2回目フォームの回答 '!W2="ときどきあった"),2,(IF(('2回目フォームの回答 '!W2="しばしばあった"),3,(IF(('2回目フォームの回答 '!W2="ほとんどいつもあった"),4,""))))))) -> 2 | AR2: =IF(('2回目フォームの回答 '!X2="ほとんどなかった"),1,(IF(('2回目フォームの回答 '!X2="ときどきあった"),2,(IF(('2回目フォームの回答 '!X2="しばしばあった"),3,(IF(('2回目フォームの回答 '!X2="ほとんどいつもあった"),4,""))))))) -> 2 | AS2: =IF(('2回目フォームの回答 '!Y2="ほとんどなかった"),1,(IF(('2回目フォームの回答 '!Y2="ときどきあった"),2,(IF(('2回目フォームの回答 '!Y2="しばしばあった"),3,(IF(('2回目フォームの回答 '!Y2="ほとんどいつもあった"),4,""))))))) -> 2 | AT2: =IF(('2回目フォームの回答 '!Z2="ほとんどなかった"),1,(IF(('2回目フォームの回答 '!Z2="ときどきあった"),2,(IF(('2回目フォームの回答 '!Z2="しばしばあった"),3,(IF(('2回目フォームの回答 '!Z2="ほとんどいつもあった"),4,""))))))) -> 3 | AU2: =IF(('2回目フォームの回答 '!AA2="ほとんどなかった"),1,(IF(('2回目フォームの回答 '!AA2="ときどきあった"),2,(IF(('2回目フォームの回答 '!AA2="しばしばあった"),3,(IF(('2回目フォームの回答 '!AA2="ほとんどいつもあった"),4,""))))))) -> 3 | AV2: =IF(('2回目フォームの回答 '!AB2="ほとんどなかった"),1,(IF(('2回目フォームの回答 '!AB2="ときどきばあった"),2,(IF(('2回目フォームの回答 '!AB2="しばしばあった"),3,(IF(('2回目フォームの回答 '!AB2="ほとんどいつもあった"),4,""))))))) -> 3 | AW2: =IF(('2回目フォームの回答 '!AC2="ほとんどなかった"),1,(IF(('2回目フォームの回答 '!AC2="ときどきあった"),2,(IF(('2回目フォームの回答 '!AC2="しばしばあった"),3,(IF(('2回目フォームの回答 '!AC2="ほとんどいつもあった"),4,""))))))) -> 2 | AX2: =IF(('2回目フォームの回答 '!AD2="ほとんどなかった"),1,(IF(('2回目フォームの回答 '!AD2="ときどきあった"),2,(IF(('2回目フォームの回答 '!AD2="しばしばあった"),3,(IF(('2回目フォームの回答 '!AD2="ほとんどいつもあった"),4,""))))))) -> 3 | AY2: =IF(('2回目フォームの回答 '!AE2="ほとんどなかった"),1,(IF(('2回目フォームの回答 '!AE2="ときどきあった"),2,(IF(('2回目フォームの回答 '!AE2="しばしばあった"),3,(IF(('2回目フォームの回答 '!AE2="ほとんどいつもあった"),4,""))))))) -> 2 | AZ2: =IF(('2回目フォームの回答 '!AF2="ほとんどなかった"),1,(IF(('2回目フォームの回答 '!AF2="ときどきあった"),2,(IF(('2回目フォームの回答 '!AF2="しばしばあった"),3,(IF(('2回目フォームの回答 '!AF2="ほとんどいつもあった"),4,""))))))) -> 4 | BA2: =IF(('2回目フォームの回答 '!AG2="ほとんどなかった"),1,(IF(('2回目フォームの回答 '!AG2="ときどきあった"),2,(IF(('2回目フォームの回答 '!AG2="しばしばあった"),3,(IF(('2回目フォームの回答 '!AG2="ほとんどいつもあった"),4,""))))))) -> 2 | BB2: =IF(('2回目フォームの回答 '!AH2="ほとんどなかった"),1,(IF(('2回目フォームの回答 '!AH2="ときどきあった"),2,(IF(('2回目フォームの回答 '!AH2="しばしばあった"),3,(IF(('2回目フォームの回答 '!AH2="ほとんどいつもあった"),4,""))))))) -> 3 | BC2: =IF(('2回目フォームの回答 '!AI2="ほとんどなかった"),1,(IF(('2回目フォームの回答 '!AI2="ときどきあった"),2,(IF(('2回目フォームの回答 '!AI2="しばしばあった"),3,(IF(('2回目フォームの回答 '!AI2="ほとんどいつもあった"),4,""))))))) -> 2 | BD2: =IF(('2回目フォームの回答 '!AJ2="ほとんどなかった"),1,(IF(('2回目フォームの回答 '!AJ2="ときどきあった"),2,(IF(('2回目フォームの回答 '!AJ2="しばしばあった"),3,(IF(('2回目フォームの回答 '!AJ2="ほとんどいつもあった"),4,""))))))) -> 2 | ... BP2: =IF(('2回目フォームの回答 '!AV2="ほとんどなかった"),1,(IF(('2回目フォームの回答 '!AV2="ときどきあった"),2,(IF(('2回目フォームの回答 '!AV2="しばしばあった"),3,(IF(('2回目フォームの回答 '!AV2="ほとんどいつもあった"),4,""))))))) -> 2 | BQ2: =$AN2+$AO2+$AP2 -> 4 | BR2: =IF((BQ2=3),5,(IF(AND(BQ2>=4,BQ2<=5),4,(IF(AND(BQ2>=6,BQ2<=7),3,(IF(AND(BQ2>=8,BQ2<=9),2,IF(BQ2>=10,1,"")))))))) -> 4 | BS2: =$AQ2+$AR2+$AS2 -> 6 | BT2: =IF(AND(B2="male",BS2=3),1,(IF(AND(B2="male",BS2>=4,BS2<=5),2,(IF(AND(B2="male",BS2>=6,BS2<=7),3,(IF(AND(B2="male",BS2>=8,BS2<=9),4,IF(AND(B2="male",BS2>=10),5,IF(AND(B2="female",BS2=3),1,(IF(AND(B2="female",BS2>=4,BS2<=5),2,(IF(AND(B2="female",BS2>=6,BS2<=8),3,(IF(AND(B2="female",BS2>=9,BS2<=10),4,IF(AND(B2="female",BS2>=11),5,"")))))))))))))))) -> 3 | BU2: =$AT2+$AU2+$AV2 -> 9 | BV2: =IF(AND(B2="male",BU2=3),1,(IF(AND(B2="male",BU2=4),2,(IF(AND(B2="male",BU2>=5,BU2<=7),3,(IF(AND(B2="male",BU2>=8,BU2<=10),4,IF(AND(B2="male",BU2>=11),5,IF(AND(B2="female",BU2=3),1,(IF(AND(B2="female",BU2>=4,BU2<=5),2,(IF(AND(B2="female",BU2>=6,BU2<=8),3,(IF(AND(B2="female",BU2>=9,BU2<=11),4,IF(AND(B2="female",BU2>=12),5,"")))))))))))))))) -> 4 | BW2: =$AW2+$AX2+$AY2 -> 7 | BX2: =IF(AND(B2="male",BW2=3),1,(IF(AND(B2="male",BW2=4),2,(IF(AND(B2="male",BW2>=5,BW2<=7),3,(IF(AND(B2="male",BW2>=8,BW2<=9),4,(IF(AND(B2="male",BW2>=10),5,(IF(AND(B2="female",BW2=3),1,(IF(AND(B2="female",BW2=4),2,(IF(AND(B2="female",BW2>=5,BW2<=7),3,(IF(AND(B2="female",BW2>=8,BW2<=10),4,IF(AND(B2="female",BW2>=11),5,"")))))))))))))))))) -> 3 | BY2: =SUM($AZ2:$BE2) -> 15 | BZ2: =IF(AND(B2="male",BY2=6),1,(IF(AND(B2="male",BY2>=7,BY2<=8),2,(IF(AND(B2="male",BY2>=9,BY2<=12),3,(IF(AND(B2="male",BY2>=13,BY2<=16),4,IF(AND(B2="male",BY2>=17),5,IF(AND(B2="female",BY2=6),1,(IF(AND(B2="female",BY2>=7,BY2<=8),2,(IF(AND(B2="female",BY2>=9,BY2<=12),3,(IF(AND(B2="female",BY2>=13,BY2<=17),4,IF(AND(B2="female",BY2>=18),5,"")))))))))))))))) -> 4 | CA2: =SUM($BF2:$BP2) -> 21 | CB2: =IF(AND(B2="male",CA2=11),1,(IF(AND(B2="male",CA2>=12,CA2<=15),2,(IF(AND(B2="male",CA2>=16,CA2<=21),3,(IF(AND(B2="male",CA2>=22,CA2<=26),4,IF(AND(B2="male",CA2>=27),5,IF(AND(B2="female",CA2<=13),1,(IF(AND(B2="female",CA2>=14,CA2<=17),2,(IF(AND(B2="female",CA2>=18,CA2<=23),3,(IF(AND(B2="female",CA2>=24,CA2<=29),4,IF(AND(B2="female",CA2>=30),5,"")))))))))))))))) -> 3 | CC2: =IF(('2回目フォームの回答 '!AW2="非常に"),1,(IF(('2回目フォームの回答 '!AW2="かなり"),2,(IF(('2回目フォームの回答 '!AW2="多少"),3,(IF(('2回目フォームの回答 '!AW2="全くない"),4,""))))))) -> 2 | CD2: =IF(('2回目フォームの回答 '!AX2="非常に"),1,(IF(('2回目フォームの回答 '!AX2="かなり"),2,(IF(('2回目フォームの回答 '!AX2="多少"),3,(IF(('2回目フォームの回答 '!AX2="全くない"),4,""))))))) -> 2 | CE2: =IF(('2回目フォームの回答 '!AY2="非常に"),1,(IF(('2回目フォームの回答 '!AY2="かなり"),2,(IF(('2回目フォームの回答 '!AY2="多少"),3,(IF(('2回目フォームの回答 '!AY2="全くない"),4,""))))))) -> 3 | CF2: =IF(('2回目フォームの回答 '!AZ2="非常に"),1,(IF(('2回目フォームの回答 '!AZ2="かなり"),2,(IF(('2回目フォームの回答 '!AZ2="多少"),3,(IF(('2回目フォームの回答 '!AZ2="全くない"),4,""))))))) -> 2 | CG2: =IF(('2回目フォームの回答 '!BA2="非常に"),1,(IF(('2回目フォームの回答 '!BA2="かなり"),2,(IF(('2回目フォームの回答 '!BA2="多少"),3,(IF(('2回目フォームの回答 '!BA2="全くない"),4,""))))))) -> 3 | CH2: =IF(('2回目フォームの回答 '!BB2="非常に"),1,(IF(('2回目フォームの回答 '!BB2="かなり"),2,(IF(('2回目フォームの回答 '!BB2="多少"),3,(IF(('2回目フォームの回答 '!BB2="全くない"),4,""))))))) -> 3 | CI2: =IF(('2回目フォームの回答 '!BC2="非常に"),1,(IF(('2回目フォームの回答 '!BC2="かなり"),2,(IF(('2回目フォームの回答 '!BC2="多少"),3,(IF(('2回目フォームの回答 '!BC2="全くない"),4,""))))))) -> 2 | CJ2: =IF(('2回目フォームの回答 '!BD2="非常に"),1,(IF(('2回目フォームの回答 '!BD2="かなり"),2,(IF(('2回目フォームの回答 '!BD2="多少"),3,(IF(('2回目フォームの回答 '!BD2="全くない"),4,""))))))) -> 3 | CK2: =IF(('2回目フォームの回答 '!BE2="非常に"),1,(IF(('2回目フォームの回答 '!BE2="かなり"),2,(IF(('2回目フォームの回答 '!BE2="多少"),3,(IF(('2回目フォームの回答 '!BE2="全くない"),4,""))))))) -> 2 | CL2: =IF(('2回目フォームの回答 '!BF2="満足"),1,(IF(('2回目フォームの回答 '!BF2="まぁ満足"),2,(IF(('2回目フォームの回答 '!BF2="やや満足"),3,(IF(('2回目フォームの回答 '!BF2="不満足"),4,""))))))) -> 3 | CM2: =IF(('2回目フォームの回答 '!BG2="満足"),1,(IF(('2回目フォームの回答 '!BG2="まぁ満足"),2,(IF(('2回目フォームの回答 '!BG2="やや満足"),3,(IF(('2回目フォームの回答 '!BG2="不満足"),4,""))))))) -> 3 | CN2: =15-($CC2+$CF2+$CI2) -> 9 | CO2: =IF(AND(B2="male",CN2<=4),5,(IF(AND(B2="male",CN2>=5,CN2<=6),4,(IF(AND(B2="male",CN2>=7,CN2<=8),3,(IF(AND(B2="male",CN2>=9,CN2<=10),2,IF(AND(B2="male",CN2>=11),1,IF(AND(B2="female",CN2<=3),5,(IF(AND(B2="female",CN2>=4,CN2<=5),4,(IF(AND(B2="female",CN2>=6,CN2<=7),3,(IF(AND(B2="female",CN2>=8,CN2<=10),2,IF(AND(B2="female",CN2>=11),1,"")))))))))))))))) -> 2 | CP2: =15-($CD2+$CG2+$CJ2) -> 7 | CQ2: =IF((CP2<=5),5,(IF(AND(CP2>=6,CP2<=7),4,(IF(AND(CP2>=8,CP2<=9),3,(IF(AND(CP2>=10,AF2<=11),2,IF(AF2>=12,1,"")))))))) -> 4 | CR2: =15-($CE2+$CH2+$CK2) -> 7 | CS2: =IF((CR2<=6),5,(IF(AND(CR2>=7,CR2<=8),4,IF((CR2=9),3,IF(AND(CR2>=10,CR2<=11),2,IF(CR2>=12,1,"")))))) -> 4 | CT2: =10-($CL2+$CM2) -> 4 | CU2: =IF((CT2<=3),5,(IF((CT2=4),4,IF(AND(CT2>=5,CT2<=6),3,IF((CT2=7),2,IF(CT2>=8,1,"")))))) -> 4 | CV2: =BR2+BT2+BV2+BX2+BZ2+CB2 -> 21 | CW2: =W2+Y2+AA2+AC2+AE2+AG2+AI2+AK2+AM2 -> 28 | CX2: =CO2+CQ2+CS2 -> 10 | CY2: =IF((CV2>=24),"高",IF(AND(CV2>=19,CV2<=23,(CW2+CX2)>=46),"高",IF(AND(CV2>=19,CV2<=23,(CW2+CX2)>=12,(CW2+CX2)<=45),"中①",IF(AND(CV2>=6,CV2<=18,(CW2+CX2)>=46),"中②","低")))) -> 中① | CZ2: ='2回目フォームの回答 '!BH2 -> 0.75 | DA2: =1-CZ3 -> 0.3 | DB2: =IF(('2回目フォームの回答 '!BI2="いつもより寝つきは良い"),0,(IF(('2回目フォームの回答 '!BI2="いつもより少し時間がかかった"),1,(IF(('2回目フォームの回答 '!BI2="いつもよりかなり時間がかかった"),2,(IF(('2回目フォームの回答 '!BI2="いつもより非常に時間がかかった、あるいは全く眠れなかった"),3,""))))))) -> 1 | DC2: =IF(('2回目フォームの回答 '!BJ2="問題になるほどのことはなかった"),0,(IF(('2回目フォームの回答 '!BJ2="少し困ることがある"),1,(IF(('2回目フォームの回答 '!BJ2="かなり困っている"),2,(IF(('2回目フォームの回答 '!BJ2="深刻な状態、あるいは全く眠れなかった"),3,""))))))) -> 0 | DD2: =IF(('2回目フォームの回答 '!BK2="そのようなことはなかった"),0,(IF(('2回目フォームの回答 '!BK2="少し早かった"),1,(IF(('2回目フォームの回答 '!BK2="かなり早かった"),2,(IF(('2回目フォームの回答 '!BK2="非常に早かった、あるいは全く眠れなかった"),3,""))))))) -> 0 | DE2: =IF(('2回目フォームの回答 '!BL2="十分である"),0,(IF(('2回目フォームの回答 '!BL2="少し足りない"),1,(IF(('2回目フォームの回答 '!BL2="かなり足りない"),2,(IF(('2回目フォームの回答 '!BL2="全く足りない、あるいは全く眠れなかった"),3,""))))))) -> 1 | DF2: =IF(('2回目フォームの回答 '!BM2="満足している"),0,(IF(('2回目フォームの回答 '!BM2="少し不満である"),1,(IF(('2回目フォームの回答 '!BM2="かなり不満である"),2,(IF(('2回目フォームの回答 '!BM2="非常に不満である、あるいは全く眠れなかった"),3,""))))))) -> 2 | DG2: =IF(('2回目フォームの回答 '!BN2="いつもどおり"),0,(IF(('2回目フォームの回答 '!BN2="少し滅入った"),1,(IF(('2回目フォームの回答 '!BN2="かなり滅入った"),2,(IF(('2回目フォームの回答 '!BN2="非常に滅入った"),3,""))))))) -> 2 | DH2: =IF(('2回目フォームの回答 '!BO2="いつもどおり"),0,(IF(('2回目フォームの回答 '!BO2="少し低下した"),1,(IF(('2回目フォームの回答 '!BO2="かなり低下した"),2,(IF(('2回目フォームの回答 '!BO2="非常に低下した"),3,""))))))) -> 1 | DI2: =IF(('2回目フォームの回答 '!BP2="全くなかった"),0,(IF(('2回目フォームの回答 '!BP2="少しあった"),1,(IF(('2回目フォームの回答 '!BP2="かなりあった"),2,(IF(('2回目フォームの回答 '!BP2="激しかった"),3,""))))))) -> 1 | DJ2: =SUM(DB2:DI2) -> 8 | DK2: =IF((DJ2<=3),"低",(IF(AND(DJ2>=4,DJ2<=5),"中",(IF((DJ2>=6),"高",""))))) -> 高 | DL2: 21.1 | DM2: 17.7 | DN2: 31.7 | DO2: =DL2+DM2+DN2 -> 70.5 | DQ2: 〇 | DS2: 0.29861111 | DT2: 322 | DU2: =INDEX('1回目結果'!DR:DR,MATCH($DT2,'1回目結果'!$A:$A,0)) -> 0.632 | DV2: =INDEX('1回目結果'!DS:DS,MATCH($DT2,'1回目結果'!$A:$A,0)) -> 71.75 | DW2: =INDEX('1回目結果'!DT:DT,MATCH($DT2,'1回目結果'!$A:$A,0)) -> 0.88 | DX2: =INDEX('1回目結果'!DU:DU,MATCH($DT2,'1回目結果'!$A:$A,0)) -> 44 | DY2: =IFERROR(INDEX('1回目結果'!DL:DL,MATCH('2回目結果'!$DT2,'1回目結果'!$A:$A,0)),"") -> 20.8 | DZ2: =IFERROR(INDEX('1回目結果'!DM:DM,MATCH('2回目結果'!$DT2,'1回目結果'!$A:$A,0)),"") -> 15.8 | EA2: =IFERROR(INDEX('1回目結果'!DN:DN,MATCH('2回目結果'!$DT2,'1回目結果'!$A:$A,0)),"") -> 10.9 | EB2: =IFERROR(INDEX('1回目結果'!DO:DO,MATCH('2回目結果'!$DT2,'1回目結果'!$A:$A,0)),"") -> 47.5 | EC2: =IFERROR(INDEX('1回目結果'!DP:DP,MATCH('2回目結果'!$DT2,'1回目結果'!$A:$A,0)),"") -> 0 | ED2: =IFERROR(INDEX('1回目結果'!DQ:DQ,MATCH('2回目結果'!$DT2,'1回目結果'!$A:$A,0)),"") -> 0 | EE2: 1.592 | EF2: 99.15 | EG2: 1.61 | EH2: 77 | EI2: メンタルアラートあり（+） | EJ2: =EH2/DX2 -> 1.75 | EK2: =EG2/DW2 -> 1.8295455 | EL2: =DO2-EB2 -> 23 | EM2: =DN2-EA2 -> 20.8
A3: 321 | B3: female | C3: 34254 | D3: 30 | E3: =IF(('2回目フォームの回答 '!C3="そうだ"),1,(IF(('2回目フォームの回答 '!C3="まぁそうだ"),2,(IF(('2回目フォームの回答 '!C3="ややちがう"),3,(IF(('2回目フォームの回答 '!C3="ちがう"),4,""))))))) -> 2 | F3: =IF(('2回目フォームの回答 '!D3="そうだ"),1,(IF(('2回目フォームの回答 '!D3="まぁそうだ"),2,(IF(('2回目フォームの回答 '!D3="ややちがう"),3,(IF(('2回目フォームの回答 '!D3="ちがう"),4,""))))))) -> 2 | G3: =IF(('2回目フォームの回答 '!E3="そうだ"),1,(IF(('2回目フォームの回答 '!E3="まぁそうだ"),2,(IF(('2回目フォームの回答 '!E3="ややちがう"),3,(IF(('2回目フォームの回答 '!E3="ちがう"),4,""))))))) -> 2 | H3: =IF(('2回目フォームの回答 '!F3="そうだ"),1,(IF(('2回目フォームの回答 '!F3="まぁそうだ"),2,(IF(('2回目フォームの回答 '!F3="ややちがう"),3,(IF(('2回目フォームの回答 '!F3="ちがう"),4,""))))))) -> 2 | I3: =IF(('2回目フォームの回答 '!G3="そうだ"),1,(IF(('2回目フォームの回答 '!G3="まぁそうだ"),2,(IF(('2回目フォームの回答 '!G3="ややちがう"),3,(IF(('2回目フォームの回答 '!G3="ちがう"),4,""))))))) -> 2 | J3: =IF(('2回目フォームの回答 '!H3="そうだ"),1,(IF(('2回目フォームの回答 '!H3="まぁそうだ"),2,(IF(('2回目フォームの回答 '!H3="ややちがう"),3,(IF(('2回目フォームの回答 '!H3="ちがう"),4,""))))))) -> 1 | K3: =IF(('2回目フォームの回答 '!I3="そうだ"),1,(IF(('2回目フォームの回答 '!I3="まぁそうだ"),2,(IF(('2回目フォームの回答 '!I3="ややちがう"),3,(IF(('2回目フォームの回答 '!I3="ちがう"),4,""))))))) -> 4 | L3: =IF(('2回目フォームの回答 '!J3="そうだ"),1,(IF(('2回目フォームの回答 '!J3="まぁそうだ"),2,(IF(('2回目フォームの回答 '!J3="ややちがう"),3,(IF(('2回目フォームの回答 '!J3="ちがう"),4,""))))))) -> 3 | ... U3: =IF(('2回目フォームの回答 '!S3="そうだ"),1,(IF(('2回目フォームの回答 '!S3="まぁそうだ"),2,(IF(('2回目フォームの回答 '!S3="ややちがう"),3,(IF(('2回目フォームの回答 '!S3="ちがう"),4,""))))))) -> 2 | V3: =15-($E3+$F3+$G3) -> 9 | W3: =IF(AND(B3="male",V3<=5),1,(IF(AND(B3="male",V3>=6,V3<=7),2,(IF(AND(B3="male",V3>=8,V3<=9),3,(IF(AND(B3="male",V3>=10,V3<=11),4,IF(AND(B3="male",V3>=12),5,IF(AND(B3="female",V3<=4),1,(IF(AND(B3="female",V3>=5,V3<=6),2,(IF(AND(B3="female",V3>=7,V3<=9),3,(IF(AND(B3="female",V3>=10,V3<=11),4,IF(AND(B3="female",V3>=12),5,"")))))))))))))))) -> 3 | X3: =15-($H3+$I3+$J3) -> 10 | Y3: =IF(AND(B3="male",X3<=5),1,(IF(AND(B3="male",X3>=6,X3<=7),2,(IF(AND(B3="male",X3>=8,X3<=9),3,(IF(AND(B3="male",X3>=10,X3<=11),4,IF(AND(B3="male",X3>=12),5,IF(AND(B3="female",X3<=4),1,(IF(AND(B3="female",X3>=5,X3<=6),2,(IF(AND(B3="female",X3>=7,X3<=8),3,(IF(AND(B3="female",X3>=9,X3<=10),4,IF(AND(B3="female",X3>=11),5,"")))))))))))))))) -> 4 | Z3: =5-$K3 -> 1 | AA3: =IF(Z3=1,2,IF(Z3=2,3,(IF(Z3=3,4,(IF(Z3=4,5,"")))))) -> 2 | AB3: =10-($P3+Q3)+$R3 -> 6 | AC3: =IF((AB3=3),1,(IF(AND(AB3>=4,AB3<=5),2,(IF(AND(AB3>=6,AB3<=7),3,(IF(AND(AB3>=8,AB3<=9),4,IF(AB3>=10,5,"")))))))) -> 3 | AD3: =5-$S3 -> 3 | AE3: =IF(AND(B3="male",AD3=1),2,IF(AND(B3="male",AD3=2),3,(IF(AND(B3="male",AD3=3),4,(IF(AND(B3="male",AD3=4),5,IF(AND(B3="female",AD3=1),1,IF(AND(B3="female",AD3=2),3,(IF(AND(B3="female",AD3=3),4,(IF(AND(B3="female",AD3=4),5,"")))))))))))) -> 4 | AF3: =15-($L3+$M3+$N3) -> 7 | AG3: =IF(AND(B3="male",AF3<=4),5,(IF(AND(B3="male",AF3>=5,AF3<=6),4,(IF(AND(B3="male",AF3>=7,AF3<=8),3,(IF(AND(B3="male",AF3>=9,AF3<=10),2,IF(AND(B3="male",AF3>=11),1,IF(AND(B3="female",AF3<=3),5,(IF(AND(B3="female",AF3>=4,AF3<=5),4,(IF(AND(B3="female",AF3>=6,AF3<=8),3,(IF(AND(B3="female",AF3>=9,AF3<=10),2,IF(AND(B3="female",AF3>=11),1,"")))))))))))))))) -> 3 | AH3: =$O3 -> 3 | AI3: =IF(AH3=1,5,IF(AH3=2,4,(IF(AH3=3,3,(IF(AH3=4,2,"")))))) -> 3 | AJ3: =5-$T3 -> 3 | AK3: =IF(AJ3=1,5,IF(AJ3=2,4,(IF(AJ3=3,3,(IF(AJ3=4,1,"")))))) -> 3 | AL3: =5-$U3 -> 3 | AM3: =IF(AL3=1,5,IF(AL3=2,4,(IF(AL3=3,3,(IF(AL3=4,1,"")))))) -> 3 | AN3: =IF(('2回目フォームの回答 '!T3="ほとんどなかった"),1,(IF(('2回目フォームの回答 '!T3="ときどきあった"),2,(IF(('2回目フォームの回答 '!T3="しばしばあった"),3,(IF(('2回目フォームの回答 '!T3="ほとんどいつもあった"),4,""))))))) -> 2 | AO3: =IF(('2回目フォームの回答 '!U3="ほとんどなかった"),1,(IF(('2回目フォームの回答 '!U3="ときどきあった"),2,(IF(('2回目フォームの回答 '!U3="しばしばあった"),3,(IF(('2回目フォームの回答 '!U3="ほとんどいつもあった"),4,""))))))) -> 2 | AP3: =IF(('2回目フォームの回答 '!V3="ほとんどなかった"),1,(IF(('2回目フォームの回答 '!V3="ときどきあった"),2,(IF(('2回目フォームの回答 '!V3="しばしばあった"),3,(IF(('2回目フォームの回答 '!V3="ほとんどいつもあった"),4,""))))))) -> 2 | AQ3: =IF(('2回目フォームの回答 '!W3="ほとんどなかった"),1,(IF(('2回目フォームの回答 '!W3="ときどきあった"),2,(IF(('2回目フォームの回答 '!W3="しばしばあった"),3,(IF(('2回目フォームの回答 '!W3="ほとんどいつもあった"),4,""))))))) -> 2 | AR3: =IF(('2回目フォームの回答 '!X3="ほとんどなかった"),1,(IF(('2回目フォームの回答 '!X3="ときどきあった"),2,(IF(('2回目フォームの回答 '!X3="しばしばあった"),3,(IF(('2回目フォームの回答 '!X3="ほとんどいつもあった"),4,""))))))) -> 2 | AS3: =IF(('2回目フォームの回答 '!Y3="ほとんどなかった"),1,(IF(('2回目フォームの回答 '!Y3="ときどきあった"),2,(IF(('2回目フォームの回答 '!Y3="しばしばあった"),3,(IF(('2回目フォームの回答 '!Y3="ほとんどいつもあった"),4,""))))))) -> 2 | AT3: =IF(('2回目フォームの回答 '!Z3="ほとんどなかった"),1,(IF(('2回目フォームの回答 '!Z3="ときどきあった"),2,(IF(('2回目フォームの回答 '!Z3="しばしばあった"),3,(IF(('2回目フォームの回答 '!Z3="ほとんどいつもあった"),4,""))))))) -> 3 | AU3: =IF(('2回目フォームの回答 '!AA3="ほとんどなかった"),1,(IF(('2回目フォームの回答 '!AA3="ときどきあった"),2,(IF(('2回目フォームの回答 '!AA3="しばしばあった"),3,(IF(('2回目フォームの回答 '!AA3="ほとんどいつもあった"),4,""))))))) -> 3 | AV3: =IF(('2回目フォームの回答 '!AB3="ほとんどなかった"),1,(IF(('2回目フォームの回答 '!AB3="ときどきばあった"),2,(IF(('2回目フォームの回答 '!AB3="しばしばあった"),3,(IF(('2回目フォームの回答 '!AB3="ほとんどいつもあった"),4,""))))))) -> 3 | AW3: =IF(('2回目フォームの回答 '!AC3="ほとんどなかった"),1,(IF(('2回目フォームの回答 '!AC3="ときどきあった"),2,(IF(('2回目フォームの回答 '!AC3="しばしばあった"),3,(IF(('2回目フォームの回答 '!AC3="ほとんどいつもあった"),4,""))))))) -> 3 | AX3: =IF(('2回目フォームの回答 '!AD3="ほとんどなかった"),1,(IF(('2回目フォームの回答 '!AD3="ときどきあった"),2,(IF(('2回目フォームの回答 '!AD3="しばしばあった"),3,(IF(('2回目フォームの回答 '!AD3="ほとんどいつもあった"),4,""))))))) -> 2 | AY3: =IF(('2回目フォームの回答 '!AE3="ほとんどなかった"),1,(IF(('2回目フォームの回答 '!AE3="ときどきあった"),2,(IF(('2回目フォームの回答 '!AE3="しばしばあった"),3,(IF(('2回目フォームの回答 '!AE3="ほとんどいつもあった"),4,""))))))) -> 1 | AZ3: =IF(('2回目フォームの回答 '!AF3="ほとんどなかった"),1,(IF(('2回目フォームの回答 '!AF3="ときどきあった"),2,(IF(('2回目フォームの回答 '!AF3="しばしばあった"),3,(IF(('2回目フォームの回答 '!AF3="ほとんどいつもあった"),4,""))))))) -> 2 | BA3: =IF(('2回目フォームの回答 '!AG3="ほとんどなかった"),1,(IF(('2回目フォームの回答 '!AG3="ときどきあった"),2,(IF(('2回目フォームの回答 '!AG3="しばしばあった"),3,(IF(('2回目フォームの回答 '!AG3="ほとんどいつもあった"),4,""))))))) -> 3 | BB3: =IF(('2回目フォームの回答 '!AH3="ほとんどなかった"),1,(IF(('2回目フォームの回答 '!AH3="ときどきあった"),2,(IF(('2回目フォームの回答 '!AH3="しばしばあった"),3,(IF(('2回目フォームの回答 '!AH3="ほとんどいつもあった"),4,""))))))) -> 3 | BC3: =IF(('2回目フォームの回答 '!AI3="ほとんどなかった"),1,(IF(('2回目フォームの回答 '!AI3="ときどきあった"),2,(IF(('2回目フォームの回答 '!AI3="しばしばあった"),3,(IF(('2回目フォームの回答 '!AI3="ほとんどいつもあった"),4,""))))))) -> 2 | BD3: =IF(('2回目フォームの回答 '!AJ3="ほとんどなかった"),1,(IF(('2回目フォームの回答 '!AJ3="ときどきあった"),2,(IF(('2回目フォームの回答 '!AJ3="しばしばあった"),3,(IF(('2回目フォームの回答 '!AJ3="ほとんどいつもあった"),4,""))))))) -> 1 | ... BP3: =IF(('2回目フォームの回答 '!AV3="ほとんどなかった"),1,(IF(('2回目フォームの回答 '!AV3="ときどきあった"),2,(IF(('2回目フォームの回答 '!AV3="しばしばあった"),3,(IF(('2回目フォームの回答 '!AV3="ほとんどいつもあった"),4,""))))))) -> 3 | BQ3: =$AN3+$AO3+$AP3 -> 6 | BR3: =IF((BQ3=3),5,(IF(AND(BQ3>=4,BQ3<=5),4,(IF(AND(BQ3>=6,BQ3<=7),3,(IF(AND(BQ3>=8,BQ3<=9),2,IF(BQ3>=10,1,"")))))))) -> 3 | BS3: =$AQ3+$AR3+$AS3 -> 6 | BT3: =IF(AND(B3="male",BS3=3),1,(IF(AND(B3="male",BS3>=4,BS3<=5),2,(IF(AND(B3="male",BS3>=6,BS3<=7),3,(IF(AND(B3="male",BS3>=8,BS3<=9),4,IF(AND(B3="male",BS3>=10),5,IF(AND(B3="female",BS3=3),1,(IF(AND(B3="female",BS3>=4,BS3<=5),2,(IF(AND(B3="female",BS3>=6,BS3<=8),3,(IF(AND(B3="female",BS3>=9,BS3<=10),4,IF(AND(B3="female",BS3>=11),5,"")))))))))))))))) -> 3 | BU3: =$AT3+$AU3+$AV3 -> 9 | BV3: =IF(AND(B3="male",BU3=3),1,(IF(AND(B3="male",BU3=4),2,(IF(AND(B3="male",BU3>=5,BU3<=7),3,(IF(AND(B3="male",BU3>=8,BU3<=10),4,IF(AND(B3="male",BU3>=11),5,IF(AND(B3="female",BU3=3),1,(IF(AND(B3="female",BU3>=4,BU3<=5),2,(IF(AND(B3="female",BU3>=6,BU3<=8),3,(IF(AND(B3="female",BU3>=9,BU3<=11),4,IF(AND(B3="female",BU3>=12),5,"")))))))))))))))) -> 4 | BW3: =$AW3+$AX3+$AY3 -> 6 | BX3: =IF(AND(B3="male",BW3=3),1,(IF(AND(B3="male",BW3=4),2,(IF(AND(B3="male",BW3>=5,BW3<=7),3,(IF(AND(B3="male",BW3>=8,BW3<=9),4,(IF(AND(B3="male",BW3>=10),5,(IF(AND(B3="female",BW3=3),1,(IF(AND(B3="female",BW3=4),2,(IF(AND(B3="female",BW3>=5,BW3<=7),3,(IF(AND(B3="female",BW3>=8,BW3<=10),4,IF(AND(B3="female",BW3>=11),5,"")))))))))))))))))) -> 3 | BY3: =SUM($AZ3:$BE3) -> 12 | BZ3: =IF(AND(B3="male",BY3=6),1,(IF(AND(B3="male",BY3>=7,BY3<=8),2,(IF(AND(B3="male",BY3>=9,BY3<=12),3,(IF(AND(B3="male",BY3>=13,BY3<=16),4,IF(AND(B3="male",BY3>=17),5,IF(AND(B3="female",BY3=6),1,(IF(AND(B3="female",BY3>=7,BY3<=8),2,(IF(AND(B3="female",BY3>=9,BY3<=12),3,(IF(AND(B3="female",BY3>=13,BY3<=17),4,IF(AND(B3="female",BY3>=18),5,"")))))))))))))))) -> 3 | CA3: =SUM($BF3:$BP3) -> 28 | CB3: =IF(AND(B3="male",CA3=11),1,(IF(AND(B3="male",CA3>=12,CA3<=15),2,(IF(AND(B3="male",CA3>=16,CA3<=21),3,(IF(AND(B3="male",CA3>=22,CA3<=26),4,IF(AND(B3="male",CA3>=27),5,IF(AND(B3="female",CA3<=13),1,(IF(AND(B3="female",CA3>=14,CA3<=17),2,(IF(AND(B3="female",CA3>=18,CA3<=23),3,(IF(AND(B3="female",CA3>=24,CA3<=29),4,IF(AND(B3="female",CA3>=30),5,"")))))))))))))))) -> 4 | CC3: =IF(('2回目フォームの回答 '!AW3="非常に"),1,(IF(('2回目フォームの回答 '!AW3="かなり"),2,(IF(('2回目フォームの回答 '!AW3="多少"),3,(IF(('2回目フォームの回答 '!AW3="全くない"),4,""))))))) -> 3 | CD3: =IF(('2回目フォームの回答 '!AX3="非常に"),1,(IF(('2回目フォームの回答 '!AX3="かなり"),2,(IF(('2回目フォームの回答 '!AX3="多少"),3,(IF(('2回目フォームの回答 '!AX3="全くない"),4,""))))))) -> 2 | CE3: =IF(('2回目フォームの回答 '!AY3="非常に"),1,(IF(('2回目フォームの回答 '!AY3="かなり"),2,(IF(('2回目フォームの回答 '!AY3="多少"),3,(IF(('2回目フォームの回答 '!AY3="全くない"),4,""))))))) -> 2 | CF3: =IF(('2回目フォームの回答 '!AZ3="非常に"),1,(IF(('2回目フォームの回答 '!AZ3="かなり"),2,(IF(('2回目フォームの回答 '!AZ3="多少"),3,(IF(('2回目フォームの回答 '!AZ3="全くない"),4,""))))))) -> 2 | CG3: =IF(('2回目フォームの回答 '!BA3="非常に"),1,(IF(('2回目フォームの回答 '!BA3="かなり"),2,(IF(('2回目フォームの回答 '!BA3="多少"),3,(IF(('2回目フォームの回答 '!BA3="全くない"),4,""))))))) -> 2 | CH3: =IF(('2回目フォームの回答 '!BB3="非常に"),1,(IF(('2回目フォームの回答 '!BB3="かなり"),2,(IF(('2回目フォームの回答 '!BB3="多少"),3,(IF(('2回目フォームの回答 '!BB3="全くない"),4,""))))))) -> 2 | CI3: =IF(('2回目フォームの回答 '!BC3="非常に"),1,(IF(('2回目フォームの回答 '!BC3="かなり"),2,(IF(('2回目フォームの回答 '!BC3="多少"),3,(IF(('2回目フォームの回答 '!BC3="全くない"),4,""))))))) -> 2 | CJ3: =IF(('2回目フォームの回答 '!BD3="非常に"),1,(IF(('2回目フォームの回答 '!BD3="かなり"),2,(IF(('2回目フォームの回答 '!BD3="多少"),3,(IF(('2回目フォームの回答 '!BD3="全くない"),4,""))))))) -> 2 | CK3: =IF(('2回目フォームの回答 '!BE3="非常に"),1,(IF(('2回目フォームの回答 '!BE3="かなり"),2,(IF(('2回目フォームの回答 '!BE3="多少"),3,(IF(('2回目フォームの回答 '!BE3="全くない"),4,""))))))) -> 2 | CL3: =IF(('2回目フォームの回答 '!BF3="満足"),1,(IF(('2回目フォームの回答 '!BF3="まぁ満足"),2,(IF(('2回目フォームの回答 '!BF3="やや満足"),3,(IF(('2回目フォームの回答 '!BF3="不満足"),4,""))))))) -> 2 | CM3: =IF(('2回目フォームの回答 '!BG3="満足"),1,(IF(('2回目フォームの回答 '!BG3="まぁ満足"),2,(IF(('2回目フォームの回答 '!BG3="やや満足"),3,(IF(('2回目フォームの回答 '!BG3="不満足"),4,""))))))) -> 2 | CN3: =15-($CC3+$CF3+$CI3) -> 8 | CO3: =IF(AND(B3="male",CN3<=4),5,(IF(AND(B3="male",CN3>=5,CN3<=6),4,(IF(AND(B3="male",CN3>=7,CN3<=8),3,(IF(AND(B3="male",CN3>=9,CN3<=10),2,IF(AND(B3="male",CN3>=11),1,IF(AND(B3="female",CN3<=3),5,(IF(AND(B3="female",CN3>=4,CN3<=5),4,(IF(AND(B3="female",CN3>=6,CN3<=7),3,(IF(AND(B3="female",CN3>=8,CN3<=10),2,IF(AND(B3="female",CN3>=11),1,"")))))))))))))))) -> 2 | CP3: =15-($CD3+$CG3+$CJ3) -> 9 | CQ3: =IF((CP3<=5),5,(IF(AND(CP3>=6,CP3<=7),4,(IF(AND(CP3>=8,CP3<=9),3,(IF(AND(CP3>=10,AF3<=11),2,IF(AF3>=12,1,"")))))))) -> 3 | CR3: =15-($CE3+$CH3+$CK3) -> 9 | CS3: =IF((CR3<=6),5,(IF(AND(CR3>=7,CR3<=8),4,IF((CR3=9),3,IF(AND(CR3>=10,CR3<=11),2,IF(CR3>=12,1,"")))))) -> 3 | CT3: =10-($CL3+$CM3) -> 6 | CU3: =IF((CT3<=3),5,(IF((CT3=4),4,IF(AND(CT3>=5,CT3<=6),3,IF((CT3=7),2,IF(CT3>=8,1,"")))))) -> 3 | CV3: =BR3+BT3+BV3+BX3+BZ3+CB3 -> 20 | CW3: =W3+Y3+AA3+AC3+AE3+AG3+AI3+AK3+AM3 -> 28 | CX3: =CO3+CQ3+CS3 -> 8 | CY3: =IF((CV3>=24),"高",IF(AND(CV3>=19,CV3<=23,(CW3+CX3)>=46),"高",IF(AND(CV3>=19,CV3<=23,(CW3+CX3)>=12,(CW3+CX3)<=45),"中①",IF(AND(CV3>=6,CV3<=18,(CW3+CX3)>=46),"中②","低")))) -> 中① | CZ3: ='2回目フォームの回答 '!BH3 -> 0.7 | DA3: =1-CZ3 -> 0.3 | DB3: =IF(('2回目フォームの回答 '!BI3="いつもより寝つきは良い"),0,(IF(('2回目フォームの回答 '!BI3="いつもより少し時間がかかった"),1,(IF(('2回目フォームの回答 '!BI3="いつもよりかなり時間がかかった"),2,(IF(('2回目フォームの回答 '!BI3="いつもより非常に時間がかかった、あるいは全く眠れなかった"),3,""))))))) -> 2 | DC3: =IF(('2回目フォームの回答 '!BJ3="問題になるほどのことはなかった"),0,(IF(('2回目フォームの回答 '!BJ3="少し困ることがある"),1,(IF(('2回目フォームの回答 '!BJ3="かなり困っている"),2,(IF(('2回目フォームの回答 '!BJ3="深刻な状態、あるいは全く眠れなかった"),3,""))))))) -> 2 | DD3: =IF(('2回目フォームの回答 '!BK3="そのようなことはなかった"),0,(IF(('2回目フォームの回答 '!BK3="少し早かった"),1,(IF(('2回目フォームの回答 '!BK3="かなり早かった"),2,(IF(('2回目フォームの回答 '!BK3="非常に早かった、あるいは全く眠れなかった"),3,""))))))) -> 0 | DE3: =IF(('2回目フォームの回答 '!BL3="十分である"),0,(IF(('2回目フォームの回答 '!BL3="少し足りない"),1,(IF(('2回目フォームの回答 '!BL3="かなり足りない"),2,(IF(('2回目フォームの回答 '!BL3="全く足りない、あるいは全く眠れなかった"),3,""))))))) -> 2 | DF3: =IF(('2回目フォームの回答 '!BM3="満足している"),0,(IF(('2回目フォームの回答 '!BM3="少し不満である"),1,(IF(('2回目フォームの回答 '!BM3="かなり不満である"),2,(IF(('2回目フォームの回答 '!BM3="非常に不満である、あるいは全く眠れなかった"),3,""))))))) -> 2 | DG3: =IF(('2回目フォームの回答 '!BN3="いつもどおり"),0,(IF(('2回目フォームの回答 '!BN3="少し滅入った"),1,(IF(('2回目フォームの回答 '!BN3="かなり滅入った"),2,(IF(('2回目フォームの回答 '!BN3="非常に滅入った"),3,""))))))) -> 1 | DH3: =IF(('2回目フォームの回答 '!BO3="いつもどおり"),0,(IF(('2回目フォームの回答 '!BO3="少し低下した"),1,(IF(('2回目フォームの回答 '!BO3="かなり低下した"),2,(IF(('2回目フォームの回答 '!BO3="非常に低下した"),3,""))))))) -> 1 | DI3: =IF(('2回目フォームの回答 '!BP3="全くなかった"),0,(IF(('2回目フォームの回答 '!BP3="少しあった"),1,(IF(('2回目フォームの回答 '!BP3="かなりあった"),2,(IF(('2回目フォームの回答 '!BP3="激しかった"),3,""))))))) -> 1 | DJ3: =SUM(DB3:DI3) -> 11 | DK3: =IF((DJ3<=3),"低",(IF(AND(DJ3>=4,DJ3<=5),"中",(IF((DJ3>=6),"高",""))))) -> 高 | DL3: 1.4 | DM3: 20.4 | DN3: 19.4 | DO3: =DL3+DM3+DN3 -> 41.2 | DP3: 〇 | DR3: 〇 | DS3: 0.29166667 | DT3: 310 | DU3: =INDEX('1回目結果'!DR:DR,MATCH($DT3,'1回目結果'!$A:$A,0)) -> 0.24 | DV3: =INDEX('1回目結果'!DS:DS,MATCH($DT3,'1回目結果'!$A:$A,0)) -> 42.5 | DW3: =INDEX('1回目結果'!DT:DT,MATCH($DT3,'1回目結果'!$A:$A,0)) -> 0.56 | DX3: =INDEX('1回目結果'!DU:DU,MATCH($DT3,'1回目結果'!$A:$A,0)) -> 10 | DY3: =IFERROR(INDEX('1回目結果'!DL:DL,MATCH('2回目結果'!$DT3,'1回目結果'!$A:$A,0)),"") -> 15.7 | DZ3: =IFERROR(INDEX('1回目結果'!DM:DM,MATCH('2回目結果'!$DT3,'1回目結果'!$A:$A,0)),"") -> 0 | EA3: =IFERROR(INDEX('1回目結果'!DN:DN,MATCH('2回目結果'!$DT3,'1回目結果'!$A:$A,0)),"") -> 2.6 | EB3: =IFERROR(INDEX('1回目結果'!DO:DO,MATCH('2回目結果'!$DT3,'1回目結果'!$A:$A,0)),"") -> 18.3 | EC3: =IFERROR(INDEX('1回目結果'!DP:DP,MATCH('2回目結果'!$DT3,'1回目結果'!$A:$A,0)),"") -> 0 | ED3: =IFERROR(INDEX('1回目結果'!DQ:DQ,MATCH('2回目結果'!$DT3,'1回目結果'!$A:$A,0)),"") -> 〇 | EE3: 1.104 | EF3: 186.64 | EG3: 0.59 | EH3: 30 | EI3: メンタルアラートなし（-） | EJ3: =EH3/DX3 -> 3 | EL3: =DO3-EB3 -> 22.9 | EM3: =DN3-EA3 -> 16.8
A4: 323 | B4: female | C4: 32706 | D4: 35 | E4: =IF(('2回目フォームの回答 '!C4="そうだ"),1,(IF(('2回目フォームの回答 '!C4="まぁそうだ"),2,(IF(('2回目フォームの回答 '!C4="ややちがう"),3,(IF(('2回目フォームの回答 '!C4="ちがう"),4,""))))))) -> 3 | F4: =IF(('2回目フォームの回答 '!D4="そうだ"),1,(IF(('2回目フォームの回答 '!D4="まぁそうだ"),2,(IF(('2回目フォームの回答 '!D4="ややちがう"),3,(IF(('2回目フォームの回答 '!D4="ちがう"),4,""))))))) -> 3 | G4: =IF(('2回目フォームの回答 '!E4="そうだ"),1,(IF(('2回目フォームの回答 '!E4="まぁそうだ"),2,(IF(('2回目フォームの回答 '!E4="ややちがう"),3,(IF(('2回目フォームの回答 '!E4="ちがう"),4,""))))))) -> 2 | H4: =IF(('2回目フォームの回答 '!F4="そうだ"),1,(IF(('2回目フォームの回答 '!F4="まぁそうだ"),2,(IF(('2回目フォームの回答 '!F4="ややちがう"),3,(IF(('2回目フォームの回答 '!F4="ちがう"),4,""))))))) -> 3 | I4: =IF(('2回目フォームの回答 '!G4="そうだ"),1,(IF(('2回目フォームの回答 '!G4="まぁそうだ"),2,(IF(('2回目フォームの回答 '!G4="ややちがう"),3,(IF(('2回目フォームの回答 '!G4="ちがう"),4,""))))))) -> 3 | J4: =IF(('2回目フォームの回答 '!H4="そうだ"),1,(IF(('2回目フォームの回答 '!H4="まぁそうだ"),2,(IF(('2回目フォームの回答 '!H4="ややちがう"),3,(IF(('2回目フォームの回答 '!H4="ちがう"),4,""))))))) -> 2 | K4: =IF(('2回目フォームの回答 '!I4="そうだ"),1,(IF(('2回目フォームの回答 '!I4="まぁそうだ"),2,(IF(('2回目フォームの回答 '!I4="ややちがう"),3,(IF(('2回目フォームの回答 '!I4="ちがう"),4,""))))))) -> 4 | L4: =IF(('2回目フォームの回答 '!J4="そうだ"),1,(IF(('2回目フォームの回答 '!J4="まぁそうだ"),2,(IF(('2回目フォームの回答 '!J4="ややちがう"),3,(IF(('2回目フォームの回答 '!J4="ちがう"),4,""))))))) -> 2 | ... U4: =IF(('2回目フォームの回答 '!S4="そうだ"),1,(IF(('2回目フォームの回答 '!S4="まぁそうだ"),2,(IF(('2回目フォームの回答 '!S4="ややちがう"),3,(IF(('2回目フォームの回答 '!S4="ちがう"),4,""))))))) -> 3 | V4: =15-($E4+$F4+$G4) -> 7 | W4: =IF(AND(B4="male",V4<=5),1,(IF(AND(B4="male",V4>=6,V4<=7),2,(IF(AND(B4="male",V4>=8,V4<=9),3,(IF(AND(B4="male",V4>=10,V4<=11),4,IF(AND(B4="male",V4>=12),5,IF(AND(B4="female",V4<=4),1,(IF(AND(B4="female",V4>=5,V4<=6),2,(IF(AND(B4="female",V4>=7,V4<=9),3,(IF(AND(B4="female",V4>=10,V4<=11),4,IF(AND(B4="female",V4>=12),5,"")))))))))))))))) -> 3 | X4: =15-($H4+$I4+$J4) -> 7 | Y4: =IF(AND(B4="male",X4<=5),1,(IF(AND(B4="male",X4>=6,X4<=7),2,(IF(AND(B4="male",X4>=8,X4<=9),3,(IF(AND(B4="male",X4>=10,X4<=11),4,IF(AND(B4="male",X4>=12),5,IF(AND(B4="female",X4<=4),1,(IF(AND(B4="female",X4>=5,X4<=6),2,(IF(AND(B4="female",X4>=7,X4<=8),3,(IF(AND(B4="female",X4>=9,X4<=10),4,IF(AND(B4="female",X4>=11),5,"")))))))))))))))) -> 3 | Z4: =5-$K4 -> 1 | AA4: =IF(Z4=1,2,IF(Z4=2,3,(IF(Z4=3,4,(IF(Z4=4,5,"")))))) -> 2 | AB4: =10-($P4+Q4)+$R4 -> 6 | AC4: =IF((AB4=3),1,(IF(AND(AB4>=4,AB4<=5),2,(IF(AND(AB4>=6,AB4<=7),3,(IF(AND(AB4>=8,AB4<=9),4,IF(AB4>=10,5,"")))))))) -> 3 | AD4: =5-$S4 -> 3 | AE4: =IF(AND(B4="male",AD4=1),2,IF(AND(B4="male",AD4=2),3,(IF(AND(B4="male",AD4=3),4,(IF(AND(B4="male",AD4=4),5,IF(AND(B4="female",AD4=1),1,IF(AND(B4="female",AD4=2),3,(IF(AND(B4="female",AD4=3),4,(IF(AND(B4="female",AD4=4),5,"")))))))))))) -> 4 | AF4: =15-($L4+$M4+$N4) -> 9 | AG4: =IF(AND(B4="male",AF4<=4),5,(IF(AND(B4="male",AF4>=5,AF4<=6),4,(IF(AND(B4="male",AF4>=7,AF4<=8),3,(IF(AND(B4="male",AF4>=9,AF4<=10),2,IF(AND(B4="male",AF4>=11),1,IF(AND(B4="female",AF4<=3),5,(IF(AND(B4="female",AF4>=4,AF4<=5),4,(IF(AND(B4="female",AF4>=6,AF4<=8),3,(IF(AND(B4="female",AF4>=9,AF4<=10),2,IF(AND(B4="female",AF4>=11),1,"")))))))))))))))) -> 2 | AH4: =$O4 -> 3 | AI4: =IF(AH4=1,5,IF(AH4=2,4,(IF(AH4=3,3,(IF(AH4=4,2,"")))))) -> 3 | AJ4: =5-$T4 -> 2 | AK4: =IF(AJ4=1,5,IF(AJ4=2,4,(IF(AJ4=3,3,(IF(AJ4=4,1,"")))))) -> 4 | AL4: =5-$U4 -> 2 | AM4: =IF(AL4=1,5,IF(AL4=2,4,(IF(AL4=3,3,(IF(AL4=4,1,"")))))) -> 4 | AN4: =IF(('2回目フォームの回答 '!T4="ほとんどなかった"),1,(IF(('2回目フォームの回答 '!T4="ときどきあった"),2,(IF(('2回目フォームの回答 '!T4="しばしばあった"),3,(IF(('2回目フォームの回答 '!T4="ほとんどいつもあった"),4,""))))))) -> 2 | AO4: =IF(('2回目フォームの回答 '!U4="ほとんどなかった"),1,(IF(('2回目フォームの回答 '!U4="ときどきあった"),2,(IF(('2回目フォームの回答 '!U4="しばしばあった"),3,(IF(('2回目フォームの回答 '!U4="ほとんどいつもあった"),4,""))))))) -> 2 | AP4: =IF(('2回目フォームの回答 '!V4="ほとんどなかった"),1,(IF(('2回目フォームの回答 '!V4="ときどきあった"),2,(IF(('2回目フォームの回答 '!V4="しばしばあった"),3,(IF(('2回目フォームの回答 '!V4="ほとんどいつもあった"),4,""))))))) -> 2 | AQ4: =IF(('2回目フォームの回答 '!W4="ほとんどなかった"),1,(IF(('2回目フォームの回答 '!W4="ときどきあった"),2,(IF(('2回目フォームの回答 '!W4="しばしばあった"),3,(IF(('2回目フォームの回答 '!W4="ほとんどいつもあった"),4,""))))))) -> 3 | AR4: =IF(('2回目フォームの回答 '!X4="ほとんどなかった"),1,(IF(('2回目フォームの回答 '!X4="ときどきあった"),2,(IF(('2回目フォームの回答 '!X4="しばしばあった"),3,(IF(('2回目フォームの回答 '!X4="ほとんどいつもあった"),4,""))))))) -> 3 | AS4: =IF(('2回目フォームの回答 '!Y4="ほとんどなかった"),1,(IF(('2回目フォームの回答 '!Y4="ときどきあった"),2,(IF(('2回目フォームの回答 '!Y4="しばしばあった"),3,(IF(('2回目フォームの回答 '!Y4="ほとんどいつもあった"),4,""))))))) -> 4 | AT4: =IF(('2回目フォームの回答 '!Z4="ほとんどなかった"),1,(IF(('2回目フォームの回答 '!Z4="ときどきあった"),2,(IF(('2回目フォームの回答 '!Z4="しばしばあった"),3,(IF(('2回目フォームの回答 '!Z4="ほとんどいつもあった"),4,""))))))) -> 4 | AU4: =IF(('2回目フォームの回答 '!AA4="ほとんどなかった"),1,(IF(('2回目フォームの回答 '!AA4="ときどきあった"),2,(IF(('2回目フォームの回答 '!AA4="しばしばあった"),3,(IF(('2回目フォームの回答 '!AA4="ほとんどいつもあった"),4,""))))))) -> 4 | AV4: =IF(('2回目フォームの回答 '!AB4="ほとんどなかった"),1,(IF(('2回目フォームの回答 '!AB4="ときどきばあった"),2,(IF(('2回目フォームの回答 '!AB4="しばしばあった"),3,(IF(('2回目フォームの回答 '!AB4="ほとんどいつもあった"),4,""))))))) -> 4 | AW4: =IF(('2回目フォームの回答 '!AC4="ほとんどなかった"),1,(IF(('2回目フォームの回答 '!AC4="ときどきあった"),2,(IF(('2回目フォームの回答 '!AC4="しばしばあった"),3,(IF(('2回目フォームの回答 '!AC4="ほとんどいつもあった"),4,""))))))) -> 4 | AX4: =IF(('2回目フォームの回答 '!AD4="ほとんどなかった"),1,(IF(('2回目フォームの回答 '!AD4="ときどきあった"),2,(IF(('2回目フォームの回答 '!AD4="しばしばあった"),3,(IF(('2回目フォームの回答 '!AD4="ほとんどいつもあった"),4,""))))))) -> 3 | AY4: =IF(('2回目フォームの回答 '!AE4="ほとんどなかった"),1,(IF(('2回目フォームの回答 '!AE4="ときどきあった"),2,(IF(('2回目フォームの回答 '!AE4="しばしばあった"),3,(IF(('2回目フォームの回答 '!AE4="ほとんどいつもあった"),4,""))))))) -> 2 | AZ4: =IF(('2回目フォームの回答 '!AF4="ほとんどなかった"),1,(IF(('2回目フォームの回答 '!AF4="ときどきあった"),2,(IF(('2回目フォームの回答 '!AF4="しばしばあった"),3,(IF(('2回目フォームの回答 '!AF4="ほとんどいつもあった"),4,""))))))) -> 2 | BA4: =IF(('2回目フォームの回答 '!AG4="ほとんどなかった"),1,(IF(('2回目フォームの回答 '!AG4="ときどきあった"),2,(IF(('2回目フォームの回答 '!AG4="しばしばあった"),3,(IF(('2回目フォームの回答 '!AG4="ほとんどいつもあった"),4,""))))))) -> 2 | BB4: =IF(('2回目フォームの回答 '!AH4="ほとんどなかった"),1,(IF(('2回目フォームの回答 '!AH4="ときどきあった"),2,(IF(('2回目フォームの回答 '!AH4="しばしばあった"),3,(IF(('2回目フォームの回答 '!AH4="ほとんどいつもあった"),4,""))))))) -> 2 | BC4: =IF(('2回目フォームの回答 '!AI4="ほとんどなかった"),1,(IF(('2回目フォームの回答 '!AI4="ときどきあった"),2,(IF(('2回目フォームの回答 '!AI4="しばしばあった"),3,(IF(('2回目フォームの回答 '!AI4="ほとんどいつもあった"),4,""))))))) -> 3 | BD4: =IF(('2回目フォームの回答 '!AJ4="ほとんどなかった"),1,(IF(('2回目フォームの回答 '!AJ4="ときどきあった"),2,(IF(('2回目フォームの回答 '!AJ4="しばしばあった"),3,(IF(('2回目フォームの回答 '!AJ4="ほとんどいつもあった"),4,""))))))) -> 2 | ... BP4: =IF(('2回目フォームの回答 '!AV4="ほとんどなかった"),1,(IF(('2回目フォームの回答 '!AV4="ときどきあった"),2,(IF(('2回目フォームの回答 '!AV4="しばしばあった"),3,(IF(('2回目フォームの回答 '!AV4="ほとんどいつもあった"),4,""))))))) -> 4 | BQ4: =$AN4+$AO4+$AP4 -> 6 | BR4: =IF((BQ4=3),5,(IF(AND(BQ4>=4,BQ4<=5),4,(IF(AND(BQ4>=6,BQ4<=7),3,(IF(AND(BQ4>=8,BQ4<=9),2,IF(BQ4>=10,1,"")))))))) -> 3 | BS4: =$AQ4+$AR4+$AS4 -> 10 | BT4: =IF(AND(B4="male",BS4=3),1,(IF(AND(B4="male",BS4>=4,BS4<=5),2,(IF(AND(B4="male",BS4>=6,BS4<=7),3,(IF(AND(B4="male",BS4>=8,BS4<=9),4,IF(AND(B4="male",BS4>=10),5,IF(AND(B4="female",BS4=3),1,(IF(AND(B4="female",BS4>=4,BS4<=5),2,(IF(AND(B4="female",BS4>=6,BS4<=8),3,(IF(AND(B4="female",BS4>=9,BS4<=10),4,IF(AND(B4="female",BS4>=11),5,"")))))))))))))))) -> 4 | BU4: =$AT4+$AU4+$AV4 -> 12 | BV4: =IF(AND(B4="male",BU4=3),1,(IF(AND(B4="male",BU4=4),2,(IF(AND(B4="male",BU4>=5,BU4<=7),3,(IF(AND(B4="male",BU4>=8,BU4<=10),4,IF(AND(B4="male",BU4>=11),5,IF(AND(B4="female",BU4=3),1,(IF(AND(B4="female",BU4>=4,BU4<=5),2,(IF(AND(B4="female",BU4>=6,BU4<=8),3,(IF(AND(B4="female",BU4>=9,BU4<=11),4,IF(AND(B4="female",BU4>=12),5,"")))))))))))))))) -> 5 | BW4: =$AW4+$AX4+$AY4 -> 9 | BX4: =IF(AND(B4="male",BW4=3),1,(IF(AND(B4="male",BW4=4),2,(IF(AND(B4="male",BW4>=5,BW4<=7),3,(IF(AND(B4="male",BW4>=8,BW4<=9),4,(IF(AND(B4="male",BW4>=10),5,(IF(AND(B4="female",BW4=3),1,(IF(AND(B4="female",BW4=4),2,(IF(AND(B4="female",BW4>=5,BW4<=7),3,(IF(AND(B4="female",BW4>=8,BW4<=10),4,IF(AND(B4="female",BW4>=11),5,"")))))))))))))))))) -> 4 | BY4: =SUM($AZ4:$BE4) -> 12 | BZ4: =IF(AND(B4="male",BY4=6),1,(IF(AND(B4="male",BY4>=7,BY4<=8),2,(IF(AND(B4="male",BY4>=9,BY4<=12),3,(IF(AND(B4="male",BY4>=13,BY4<=16),4,IF(AND(B4="male",BY4>=17),5,IF(AND(B4="female",BY4=6),1,(IF(AND(B4="female",BY4>=7,BY4<=8),2,(IF(AND(B4="female",BY4>=9,BY4<=12),3,(IF(AND(B4="female",BY4>=13,BY4<=17),4,IF(AND(B4="female",BY4>=18),5,"")))))))))))))))) -> 3 | CA4: =SUM($BF4:$BP4) -> 27 | CB4: =IF(AND(B4="male",CA4=11),1,(IF(AND(B4="male",CA4>=12,CA4<=15),2,(IF(AND(B4="male",CA4>=16,CA4<=21),3,(IF(AND(B4="male",CA4>=22,CA4<=26),4,IF(AND(B4="male",CA4>=27),5,IF(AND(B4="female",CA4<=13),1,(IF(AND(B4="female",CA4>=14,CA4<=17),2,(IF(AND(B4="female",CA4>=18,CA4<=23),3,(IF(AND(B4="female",CA4>=24,CA4<=29),4,IF(AND(B4="female",CA4>=30),5,"")))))))))))))))) -> 4 | CC4: =IF(('2回目フォームの回答 '!AW4="非常に"),1,(IF(('2回目フォームの回答 '!AW4="かなり"),2,(IF(('2回目フォームの回答 '!AW4="多少"),3,(IF(('2回目フォームの回答 '!AW4="全くない"),4,""))))))) -> 3 | CD4: =IF(('2回目フォームの回答 '!AX4="非常に"),1,(IF(('2回目フォームの回答 '!AX4="かなり"),2,(IF(('2回目フォームの回答 '!AX4="多少"),3,(IF(('2回目フォームの回答 '!AX4="全くない"),4,""))))))) -> 2 | CE4: =IF(('2回目フォームの回答 '!AY4="非常に"),1,(IF(('2回目フォームの回答 '!AY4="かなり"),2,(IF(('2回目フォームの回答 '!AY4="多少"),3,(IF(('2回目フォームの回答 '!AY4="全くない"),4,""))))))) -> 1 | CF4: =IF(('2回目フォームの回答 '!AZ4="非常に"),1,(IF(('2回目フォームの回答 '!AZ4="かなり"),2,(IF(('2回目フォームの回答 '!AZ4="多少"),3,(IF(('2回目フォームの回答 '!AZ4="全くない"),4,""))))))) -> 2 | CG4: =IF(('2回目フォームの回答 '!BA4="非常に"),1,(IF(('2回目フォームの回答 '!BA4="かなり"),2,(IF(('2回目フォームの回答 '!BA4="多少"),3,(IF(('2回目フォームの回答 '!BA4="全くない"),4,""))))))) -> 1 | CH4: =IF(('2回目フォームの回答 '!BB4="非常に"),1,(IF(('2回目フォームの回答 '!BB4="かなり"),2,(IF(('2回目フォームの回答 '!BB4="多少"),3,(IF(('2回目フォームの回答 '!BB4="全くない"),4,""))))))) -> 1 | CI4: =IF(('2回目フォームの回答 '!BC4="非常に"),1,(IF(('2回目フォームの回答 '!BC4="かなり"),2,(IF(('2回目フォームの回答 '!BC4="多少"),3,(IF(('2回目フォームの回答 '!BC4="全くない"),4,""))))))) -> 3 | CJ4: =IF(('2回目フォームの回答 '!BD4="非常に"),1,(IF(('2回目フォームの回答 '!BD4="かなり"),2,(IF(('2回目フォームの回答 '!BD4="多少"),3,(IF(('2回目フォームの回答 '!BD4="全くない"),4,""))))))) -> 2 | CK4: =IF(('2回目フォームの回答 '!BE4="非常に"),1,(IF(('2回目フォームの回答 '!BE4="かなり"),2,(IF(('2回目フォームの回答 '!BE4="多少"),3,(IF(('2回目フォームの回答 '!BE4="全くない"),4,""))))))) -> 1 | CL4: =IF(('2回目フォームの回答 '!BF4="満足"),1,(IF(('2回目フォームの回答 '!BF4="まぁ満足"),2,(IF(('2回目フォームの回答 '!BF4="やや満足"),3,(IF(('2回目フォームの回答 '!BF4="不満足"),4,""))))))) -> 3 | CM4: =IF(('2回目フォームの回答 '!BG4="満足"),1,(IF(('2回目フォームの回答 '!BG4="まぁ満足"),2,(IF(('2回目フォームの回答 '!BG4="やや満足"),3,(IF(('2回目フォームの回答 '!BG4="不満足"),4,""))))))) -> 1 | CN4: =15-($CC4+$CF4+$CI4) -> 7 | CO4: =IF(AND(B4="male",CN4<=4),5,(IF(AND(B4="male",CN4>=5,CN4<=6),4,(IF(AND(B4="male",CN4>=7,CN4<=8),3,(IF(AND(B4="male",CN4>=9,CN4<=10),2,IF(AND(B4="male",CN4>=11),1,IF(AND(B4="female",CN4<=3),5,(IF(AND(B4="female",CN4>=4,CN4<=5),4,(IF(AND(B4="female",CN4>=6,CN4<=7),3,(IF(AND(B4="female",CN4>=8,CN4<=10),2,IF(AND(B4="female",CN4>=11),1,"")))))))))))))))) -> 3 | CP4: =15-($CD4+$CG4+$CJ4) -> 10 | CQ4: =IF((CP4<=5),5,(IF(AND(CP4>=6,CP4<=7),4,(IF(AND(CP4>=8,CP4<=9),3,(IF(AND(CP4>=10,AF4<=11),2,IF(AF4>=12,1,"")))))))) -> 2 | CR4: =15-($CE4+$CH4+$CK4) -> 12 | CS4: =IF((CR4<=6),5,(IF(AND(CR4>=7,CR4<=8),4,IF((CR4=9),3,IF(AND(CR4>=10,CR4<=11),2,IF(CR4>=12,1,"")))))) -> 1 | CT4: =10-($CL4+$CM4) -> 6 | CU4: =IF((CT4<=3),5,(IF((CT4=4),4,IF(AND(CT4>=5,CT4<=6),3,IF((CT4=7),2,IF(CT4>=8,1,"")))))) -> 3 | CV4: =BR4+BT4+BV4+BX4+BZ4+CB4 -> 23 | CW4: =W4+Y4+AA4+AC4+AE4+AG4+AI4+AK4+AM4 -> 28 | CX4: =CO4+CQ4+CS4 -> 6 | CY4: =IF((CV4>=24),"高",IF(AND(CV4>=19,CV4<=23,(CW4+CX4)>=46),"高",IF(AND(CV4>=19,CV4<=23,(CW4+CX4)>=12,(CW4+CX4)<=45),"中①",IF(AND(CV4>=6,CV4<=18,(CW4+CX4)>=46),"中②","低")))) -> 中① | CZ4: ='2回目フォームの回答 '!BH4 -> 0.7 | DA4: =1-CZ4 -> 0.3 | DB4: =IF(('2回目フォームの回答 '!BI4="いつもより寝つきは良い"),0,(IF(('2回目フォームの回答 '!BI4="いつもより少し時間がかかった"),1,(IF(('2回目フォームの回答 '!BI4="いつもよりかなり時間がかかった"),2,(IF(('2回目フォームの回答 '!BI4="いつもより非常に時間がかかった、あるいは全く眠れなかった"),3,""))))))) -> 1 | DC4: =IF(('2回目フォームの回答 '!BJ4="問題になるほどのことはなかった"),0,(IF(('2回目フォームの回答 '!BJ4="少し困ることがある"),1,(IF(('2回目フォームの回答 '!BJ4="かなり困っている"),2,(IF(('2回目フォームの回答 '!BJ4="深刻な状態、あるいは全く眠れなかった"),3,""))))))) -> 2 | DD4: =IF(('2回目フォームの回答 '!BK4="そのようなことはなかった"),0,(IF(('2回目フォームの回答 '!BK4="少し早かった"),1,(IF(('2回目フォームの回答 '!BK4="かなり早かった"),2,(IF(('2回目フォームの回答 '!BK4="非常に早かった、あるいは全く眠れなかった"),3,""))))))) -> 1 | DE4: =IF(('2回目フォームの回答 '!BL4="十分である"),0,(IF(('2回目フォームの回答 '!BL4="少し足りない"),1,(IF(('2回目フォームの回答 '!BL4="かなり足りない"),2,(IF(('2回目フォームの回答 '!BL4="全く足りない、あるいは全く眠れなかった"),3,""))))))) -> 2 | DF4: =IF(('2回目フォームの回答 '!BM4="満足している"),0,(IF(('2回目フォームの回答 '!BM4="少し不満である"),1,(IF(('2回目フォームの回答 '!BM4="かなり不満である"),2,(IF(('2回目フォームの回答 '!BM4="非常に不満である、あるいは全く眠れなかった"),3,""))))))) -> 2 | DG4: =IF(('2回目フォームの回答 '!BN4="いつもどおり"),0,(IF(('2回目フォームの回答 '!BN4="少し滅入った"),1,(IF(('2回目フォームの回答 '!BN4="かなり滅入った"),2,(IF(('2回目フォームの回答 '!BN4="非常に滅入った"),3,""))))))) -> 2 | DH4: =IF(('2回目フォームの回答 '!BO4="いつもどおり"),0,(IF(('2回目フォームの回答 '!BO4="少し低下した"),1,(IF(('2回目フォームの回答 '!BO4="かなり低下した"),2,(IF(('2回目フォームの回答 '!BO4="非常に低下した"),3,""))))))) -> 0 | DI4: =IF(('2回目フォームの回答 '!BP4="全くなかった"),0,(IF(('2回目フォームの回答 '!BP4="少しあった"),1,(IF(('2回目フォームの回答 '!BP4="かなりあった"),2,(IF(('2回目フォームの回答 '!BP4="激しかった"),3,""))))))) -> 3 | DJ4: =SUM(DB4:DI4) -> 13 | DK4: =IF((DJ4<=3),"低",(IF(AND(DJ4>=4,DJ4<=5),"中",(IF((DJ4>=6),"高",""))))) -> 高 | DL4: 0.4 | DM4: 0.2 | DN4: 1.5 | DO4: =DL4+DM4+DN4 -> 2.1 | DS4: 0.36944444 | DT4: 304 | DU4: =INDEX('1回目結果'!DR:DR,MATCH($DT4,'1回目結果'!$A:$A,0)) -> 0.824 | DV4: =INDEX('1回目結果'!DS:DS,MATCH($DT4,'1回目結果'!$A:$A,0)) -> 116.69 | DW4: =INDEX('1回目結果'!DT:DT,MATCH($DT4,'1回目結果'!$A:$A,0)) -> 0.71 | DX4: =INDEX('1回目結果'!DU:DU,MATCH($DT4,'1回目結果'!$A:$A,0)) -> 36 | DY4: =IFERROR(INDEX('1回目結果'!DL:DL,MATCH('2回目結果'!$DT4,'1回目結果'!$A:$A,0)),"") -> 0.1 | DZ4: =IFERROR(INDEX('1回目結果'!DM:DM,MATCH('2回目結果'!$DT4,'1回目結果'!$A:$A,0)),"") -> 0.9 | EA4: =IFERROR(INDEX('1回目結果'!DN:DN,MATCH('2回目結果'!$DT4,'1回目結果'!$A:$A,0)),"") -> 1.2 | EB4: =IFERROR(INDEX('1回目結果'!DO:DO,MATCH('2回目結果'!$DT4,'1回目結果'!$A:$A,0)),"") -> 2.2 | EC4: =IFERROR(INDEX('1回目結果'!DP:DP,MATCH('2回目結果'!$DT4,'1回目結果'!$A:$A,0)),"") -> 0 | ED4: =IFERROR(INDEX('1回目結果'!DQ:DQ,MATCH('2回目結果'!$DT4,'1回目結果'!$A:$A,0)),"") -> 0 | EE4: 1.356 | EF4: 253.74 | EG4: 0.53 | EH4: 27 | EI4: メンタルアラートなし（-） | EJ4: =EH4/DX4 -> 0.75 | EK4: =EG4/DW4 -> 0.74647887 | EL4: =DO4-EB4 -> -0.1 | EM4: =DN4-EA4 -> 0.3
A5: 324 | B5: male | C5: 34739 | D5: 29 | E5: =IF(('2回目フォームの回答 '!C5="そうだ"),1,(IF(('2回目フォームの回答 '!C5="まぁそうだ"),2,(IF(('2回目フォームの回答 '!C5="ややちがう"),3,(IF(('2回目フォームの回答 '!C5="ちがう"),4,""))))))) -> 2 | F5: =IF(('2回目フォームの回答 '!D5="そうだ"),1,(IF(('2回目フォームの回答 '!D5="まぁそうだ"),2,(IF(('2回目フォームの回答 '!D5="ややちがう"),3,(IF(('2回目フォームの回答 '!D5="ちがう"),4,""))))))) -> 3 | G5: =IF(('2回目フォームの回答 '!E5="そうだ"),1,(IF(('2回目フォームの回答 '!E5="まぁそうだ"),2,(IF(('2回目フォームの回答 '!E5="ややちがう"),3,(IF(('2回目フォームの回答 '!E5="ちがう"),4,""))))))) -> 1 | H5: =IF(('2回目フォームの回答 '!F5="そうだ"),1,(IF(('2回目フォームの回答 '!F5="まぁそうだ"),2,(IF(('2回目フォームの回答 '!F5="ややちがう"),3,(IF(('2回目フォームの回答 '!F5="ちがう"),4,""))))))) -> 2 | I5: =IF(('2回目フォームの回答 '!G5="そうだ"),1,(IF(('2回目フォームの回答 '!G5="まぁそうだ"),2,(IF(('2回目フォームの回答 '!G5="ややちがう"),3,(IF(('2回目フォームの回答 '!G5="ちがう"),4,""))))))) -> 2 | J5: =IF(('2回目フォームの回答 '!H5="そうだ"),1,(IF(('2回目フォームの回答 '!H5="まぁそうだ"),2,(IF(('2回目フォームの回答 '!H5="ややちがう"),3,(IF(('2回目フォームの回答 '!H5="ちがう"),4,""))))))) -> 2 | K5: =IF(('2回目フォームの回答 '!I5="そうだ"),1,(IF(('2回目フォームの回答 '!I5="まぁそうだ"),2,(IF(('2回目フォームの回答 '!I5="ややちがう"),3,(IF(('2回目フォームの回答 '!I5="ちがう"),4,""))))))) -> 3 | L5: =IF(('2回目フォームの回答 '!J5="そうだ"),1,(IF(('2回目フォームの回答 '!J5="まぁそうだ"),2,(IF(('2回目フォームの回答 '!J5="ややちがう"),3,(IF(('2回目フォームの回答 '!J5="ちがう"),4,""))))))) -> 1 | ... U5: =IF(('2回目フォームの回答 '!S5="そうだ"),1,(IF(('2回目フォームの回答 '!S5="まぁそうだ"),2,(IF(('2回目フォームの回答 '!S5="ややちがう"),3,(IF(('2回目フォームの回答 '!S5="ちがう"),4,""))))))) -> 1 | V5: =15-($E5+$F5+$G5) -> 9 | W5: =IF(AND(B5="male",V5<=5),1,(IF(AND(B5="male",V5>=6,V5<=7),2,(IF(AND(B5="male",V5>=8,V5<=9),3,(IF(AND(B5="male",V5>=10,V5<=11),4,IF(AND(B5="male",V5>=12),5,IF(AND(B5="female",V5<=4),1,(IF(AND(B5="female",V5>=5,V5<=6),2,(IF(AND(B5="female",V5>=7,V5<=9),3,(IF(AND(B5="female",V5>=10,V5<=11),4,IF(AND(B5="female",V5>=12),5,"")))))))))))))))) -> 3 | X5: =15-($H5+$I5+$J5) -> 9 | Y5: =IF(AND(B5="male",X5<=5),1,(IF(AND(B5="male",X5>=6,X5<=7),2,(IF(AND(B5="male",X5>=8,X5<=9),3,(IF(AND(B5="male",X5>=10,X5<=11),4,IF(AND(B5="male",X5>=12),5,IF(AND(B5="female",X5<=4),1,(IF(AND(B5="female",X5>=5,X5<=6),2,(IF(AND(B5="female",X5>=7,X5<=8),3,(IF(AND(B5="female",X5>=9,X5<=10),4,IF(AND(B5="female",X5>=11),5,"")))))))))))))))) -> 3 | Z5: =5-$K5 -> 2 | AA5: =IF(Z5=1,2,IF(Z5=2,3,(IF(Z5=3,4,(IF(Z5=4,5,"")))))) -> 3 | AB5: =10-($P5+Q5)+$R5 -> 6 | AC5: =IF((AB5=3),1,(IF(AND(AB5>=4,AB5<=5),2,(IF(AND(AB5>=6,AB5<=7),3,(IF(AND(AB5>=8,AB5<=9),4,IF(AB5>=10,5,"")))))))) -> 3 | AD5: =5-$S5 -> 1 | AE5: =IF(AND(B5="male",AD5=1),2,IF(AND(B5="male",AD5=2),3,(IF(AND(B5="male",AD5=3),4,(IF(AND(B5="male",AD5=4),5,IF(AND(B5="female",AD5=1),1,IF(AND(B5="female",AD5=2),3,(IF(AND(B5="female",AD5=3),4,(IF(AND(B5="female",AD5=4),5,"")))))))))))) -> 2 | AF5: =15-($L5+$M5+$N5) -> 12 | AG5: =IF(AND(B5="male",AF5<=4),5,(IF(AND(B5="male",AF5>=5,AF5<=6),4,(IF(AND(B5="male",AF5>=7,AF5<=8),3,(IF(AND(B5="male",AF5>=9,AF5<=10),2,IF(AND(B5="male",AF5>=11),1,IF(AND(B5="female",AF5<=3),5,(IF(AND(B5="female",AF5>=4,AF5<=5),4,(IF(AND(B5="female",AF5>=6,AF5<=8),3,(IF(AND(B5="female",AF5>=9,AF5<=10),2,IF(AND(B5="female",AF5>=11),1,"")))))))))))))))) -> 1 | AH5: =$O5 -> 4 | AI5: =IF(AH5=1,5,IF(AH5=2,4,(IF(AH5=3,3,(IF(AH5=4,2,"")))))) -> 2 | AJ5: =5-$T5 -> 4 | AK5: =IF(AJ5=1,5,IF(AJ5=2,4,(IF(AJ5=3,3,(IF(AJ5=4,1,"")))))) -> 1 | AL5: =5-$U5 -> 4 | AM5: =IF(AL5=1,5,IF(AL5=2,4,(IF(AL5=3,3,(IF(AL5=4,1,"")))))) -> 1 | AN5: =IF(('2回目フォームの回答 '!T5="ほとんどなかった"),1,(IF(('2回目フォームの回答 '!T5="ときどきあった"),2,(IF(('2回目フォームの回答 '!T5="しばしばあった"),3,(IF(('2回目フォームの回答 '!T5="ほとんどいつもあった"),4,""))))))) -> 3 | AO5: =IF(('2回目フォームの回答 '!U5="ほとんどなかった"),1,(IF(('2回目フォームの回答 '!U5="ときどきあった"),2,(IF(('2回目フォームの回答 '!U5="しばしばあった"),3,(IF(('2回目フォームの回答 '!U5="ほとんどいつもあった"),4,""))))))) -> 4 | AP5: =IF(('2回目フォームの回答 '!V5="ほとんどなかった"),1,(IF(('2回目フォームの回答 '!V5="ときどきあった"),2,(IF(('2回目フォームの回答 '!V5="しばしばあった"),3,(IF(('2回目フォームの回答 '!V5="ほとんどいつもあった"),4,""))))))) -> 4 | AQ5: =IF(('2回目フォームの回答 '!W5="ほとんどなかった"),1,(IF(('2回目フォームの回答 '!W5="ときどきあった"),2,(IF(('2回目フォームの回答 '!W5="しばしばあった"),3,(IF(('2回目フォームの回答 '!W5="ほとんどいつもあった"),4,""))))))) -> 2 | AR5: =IF(('2回目フォームの回答 '!X5="ほとんどなかった"),1,(IF(('2回目フォームの回答 '!X5="ときどきあった"),2,(IF(('2回目フォームの回答 '!X5="しばしばあった"),3,(IF(('2回目フォームの回答 '!X5="ほとんどいつもあった"),4,""))))))) -> 2 | AS5: =IF(('2回目フォームの回答 '!Y5="ほとんどなかった"),1,(IF(('2回目フォームの回答 '!Y5="ときどきあった"),2,(IF(('2回目フォームの回答 '!Y5="しばしばあった"),3,(IF(('2回目フォームの回答 '!Y5="ほとんどいつもあった"),4,""))))))) -> 2 | AT5: =IF(('2回目フォームの回答 '!Z5="ほとんどなかった"),1,(IF(('2回目フォームの回答 '!Z5="ときどきあった"),2,(IF(('2回目フォームの回答 '!Z5="しばしばあった"),3,(IF(('2回目フォームの回答 '!Z5="ほとんどいつもあった"),4,""))))))) -> 2 | AU5: =IF(('2回目フォームの回答 '!AA5="ほとんどなかった"),1,(IF(('2回目フォームの回答 '!AA5="ときどきあった"),2,(IF(('2回目フォームの回答 '!AA5="しばしばあった"),3,(IF(('2回目フォームの回答 '!AA5="ほとんどいつもあった"),4,""))))))) -> 1 | AV5: =IF(('2回目フォームの回答 '!AB5="ほとんどなかった"),1,(IF(('2回目フォームの回答 '!AB5="ときどきばあった"),2,(IF(('2回目フォームの回答 '!AB5="しばしばあった"),3,(IF(('2回目フォームの回答 '!AB5="ほとんどいつもあった"),4,""))))))) -> 1 | AW5: =IF(('2回目フォームの回答 '!AC5="ほとんどなかった"),1,(IF(('2回目フォームの回答 '!AC5="ときどきあった"),2,(IF(('2回目フォームの回答 '!AC5="しばしばあった"),3,(IF(('2回目フォームの回答 '!AC5="ほとんどいつもあった"),4,""))))))) -> 2 | AX5: =IF(('2回目フォームの回答 '!AD5="ほとんどなかった"),1,(IF(('2回目フォームの回答 '!AD5="ときどきあった"),2,(IF(('2回目フォームの回答 '!AD5="しばしばあった"),3,(IF(('2回目フォームの回答 '!AD5="ほとんどいつもあった"),4,""))))))) -> 2 | AY5: =IF(('2回目フォームの回答 '!AE5="ほとんどなかった"),1,(IF(('2回目フォームの回答 '!AE5="ときどきあった"),2,(IF(('2回目フォームの回答 '!AE5="しばしばあった"),3,(IF(('2回目フォームの回答 '!AE5="ほとんどいつもあった"),4,""))))))) -> 1 | AZ5: =IF(('2回目フォームの回答 '!AF5="ほとんどなかった"),1,(IF(('2回目フォームの回答 '!AF5="ときどきあった"),2,(IF(('2回目フォームの回答 '!AF5="しばしばあった"),3,(IF(('2回目フォームの回答 '!AF5="ほとんどいつもあった"),4,""))))))) -> 1 | BA5: =IF(('2回目フォームの回答 '!AG5="ほとんどなかった"),1,(IF(('2回目フォームの回答 '!AG5="ときどきあった"),2,(IF(('2回目フォームの回答 '!AG5="しばしばあった"),3,(IF(('2回目フォームの回答 '!AG5="ほとんどいつもあった"),4,""))))))) -> 1 | BB5: =IF(('2回目フォームの回答 '!AH5="ほとんどなかった"),1,(IF(('2回目フォームの回答 '!AH5="ときどきあった"),2,(IF(('2回目フォームの回答 '!AH5="しばしばあった"),3,(IF(('2回目フォームの回答 '!AH5="ほとんどいつもあった"),4,""))))))) -> 2 | BC5: =IF(('2回目フォームの回答 '!AI5="ほとんどなかった"),1,(IF(('2回目フォームの回答 '!AI5="ときどきあった"),2,(IF(('2回目フォームの回答 '!AI5="しばしばあった"),3,(IF(('2回目フォームの回答 '!AI5="ほとんどいつもあった"),4,""))))))) -> 2 | BD5: =IF(('2回目フォームの回答 '!AJ5="ほとんどなかった"),1,(IF(('2回目フォームの回答 '!AJ5="ときどきあった"),2,(IF(('2回目フォームの回答 '!AJ5="しばしばあった"),3,(IF(('2回目フォームの回答 '!AJ5="ほとんどいつもあった"),4,""))))))) -> 1 | ... BP5: =IF(('2回目フォームの回答 '!AV5="ほとんどなかった"),1,(IF(('2回目フォームの回答 '!AV5="ときどきあった"),2,(IF(('2回目フォームの回答 '!AV5="しばしばあった"),3,(IF(('2回目フォームの回答 '!AV5="ほとんどいつもあった"),4,""))))))) -> 1 | BQ5: =$AN5+$AO5+$AP5 -> 11 | BR5: =IF((BQ5=3),5,(IF(AND(BQ5>=4,BQ5<=5),4,(IF(AND(BQ5>=6,BQ5<=7),3,(IF(AND(BQ5>=8,BQ5<=9),2,IF(BQ5>=10,1,"")))))))) -> 1 | BS5: =$AQ5+$AR5+$AS5 -> 6 | BT5: =IF(AND(B5="male",BS5=3),1,(IF(AND(B5="male",BS5>=4,BS5<=5),2,(IF(AND(B5="male",BS5>=6,BS5<=7),3,(IF(AND(B5="male",BS5>=8,BS5<=9),4,IF(AND(B5="male",BS5>=10),5,IF(AND(B5="female",BS5=3),1,(IF(AND(B5="female",BS5>=4,BS5<=5),2,(IF(AND(B5="female",BS5>=6,BS5<=8),3,(IF(AND(B5="female",BS5>=9,BS5<=10),4,IF(AND(B5="female",BS5>=11),5,"")))))))))))))))) -> 3 | BU5: =$AT5+$AU5+$AV5 -> 4 | BV5: =IF(AND(B5="male",BU5=3),1,(IF(AND(B5="male",BU5=4),2,(IF(AND(B5="male",BU5>=5,BU5<=7),3,(IF(AND(B5="male",BU5>=8,BU5<=10),4,IF(AND(B5="male",BU5>=11),5,IF(AND(B5="female",BU5=3),1,(IF(AND(B5="female",BU5>=4,BU5<=5),2,(IF(AND(B5="female",BU5>=6,BU5<=8),3,(IF(AND(B5="female",BU5>=9,BU5<=11),4,IF(AND(B5="female",BU5>=12),5,"")))))))))))))))) -> 2 | BW5: =$AW5+$AX5+$AY5 -> 5 | BX5: =IF(AND(B5="male",BW5=3),1,(IF(AND(B5="male",BW5=4),2,(IF(AND(B5="male",BW5>=5,BW5<=7),3,(IF(AND(B5="male",BW5>=8,BW5<=9),4,(IF(AND(B5="male",BW5>=10),5,(IF(AND(B5="female",BW5=3),1,(IF(AND(B5="female",BW5=4),2,(IF(AND(B5="female",BW5>=5,BW5<=7),3,(IF(AND(B5="female",BW5>=8,BW5<=10),4,IF(AND(B5="female",BW5>=11),5,"")))))))))))))))))) -> 3 | BY5: =SUM($AZ5:$BE5) -> 9 | BZ5: =IF(AND(B5="male",BY5=6),1,(IF(AND(B5="male",BY5>=7,BY5<=8),2,(IF(AND(B5="male",BY5>=9,BY5<=12),3,(IF(AND(B5="male",BY5>=13,BY5<=16),4,IF(AND(B5="male",BY5>=17),5,IF(AND(B5="female",BY5=6),1,(IF(AND(B5="female",BY5>=7,BY5<=8),2,(IF(AND(B5="female",BY5>=9,BY5<=12),3,(IF(AND(B5="female",BY5>=13,BY5<=17),4,IF(AND(B5="female",BY5>=18),5,"")))))))))))))))) -> 3 | CA5: =SUM($BF5:$BP5) -> 12 | CB5: =IF(AND(B5="male",CA5=11),1,(IF(AND(B5="male",CA5>=12,CA5<=15),2,(IF(AND(B5="male",CA5>=16,CA5<=21),3,(IF(AND(B5="male",CA5>=22,CA5<=26),4,IF(AND(B5="male",CA5>=27),5,IF(AND(B5="female",CA5<=13),1,(IF(AND(B5="female",CA5>=14,CA5<=17),2,(IF(AND(B5="female",CA5>=18,CA5<=23),3,(IF(AND(B5="female",CA5>=24,CA5<=29),4,IF(AND(B5="female",CA5>=30),5,"")))))))))))))))) -> 2 | CC5: =IF(('2回目フォームの回答 '!AW5="非常に"),1,(IF(('2回目フォームの回答 '!AW5="かなり"),2,(IF(('2回目フォームの回答 '!AW5="多少"),3,(IF(('2回目フォームの回答 '!AW5="全くない"),4,""))))))) -> 1 | CD5: =IF(('2回目フォームの回答 '!AX5="非常に"),1,(IF(('2回目フォームの回答 '!AX5="かなり"),2,(IF(('2回目フォームの回答 '!AX5="多少"),3,(IF(('2回目フォームの回答 '!AX5="全くない"),4,""))))))) -> 1 | CE5: =IF(('2回目フォームの回答 '!AY5="非常に"),1,(IF(('2回目フォームの回答 '!AY5="かなり"),2,(IF(('2回目フォームの回答 '!AY5="多少"),3,(IF(('2回目フォームの回答 '!AY5="全くない"),4,""))))))) -> 1 | CF5: =IF(('2回目フォームの回答 '!AZ5="非常に"),1,(IF(('2回目フォームの回答 '!AZ5="かなり"),2,(IF(('2回目フォームの回答 '!AZ5="多少"),3,(IF(('2回目フォームの回答 '!AZ5="全くない"),4,""))))))) -> 3 | CG5: =IF(('2回目フォームの回答 '!BA5="非常に"),1,(IF(('2回目フォームの回答 '!BA5="かなり"),2,(IF(('2回目フォームの回答 '!BA5="多少"),3,(IF(('2回目フォームの回答 '!BA5="全くない"),4,""))))))) -> 3 | CH5: =IF(('2回目フォームの回答 '!BB5="非常に"),1,(IF(('2回目フォームの回答 '!BB5="かなり"),2,(IF(('2回目フォームの回答 '!BB5="多少"),3,(IF(('2回目フォームの回答 '!BB5="全くない"),4,""))))))) -> 3 | CI5: =IF(('2回目フォームの回答 '!BC5="非常に"),1,(IF(('2回目フォームの回答 '!BC5="かなり"),2,(IF(('2回目フォームの回答 '!BC5="多少"),3,(IF(('2回目フォームの回答 '!BC5="全くない"),4,""))))))) -> 2 | CJ5: =IF(('2回目フォームの回答 '!BD5="非常に"),1,(IF(('2回目フォームの回答 '!BD5="かなり"),2,(IF(('2回目フォームの回答 '!BD5="多少"),3,(IF(('2回目フォームの回答 '!BD5="全くない"),4,""))))))) -> 2 | CK5: =IF(('2回目フォームの回答 '!BE5="非常に"),1,(IF(('2回目フォームの回答 '!BE5="かなり"),2,(IF(('2回目フォームの回答 '!BE5="多少"),3,(IF(('2回目フォームの回答 '!BE5="全くない"),4,""))))))) -> 2 | CL5: =IF(('2回目フォームの回答 '!BF5="満足"),1,(IF(('2回目フォームの回答 '!BF5="まぁ満足"),2,(IF(('2回目フォームの回答 '!BF5="やや満足"),3,(IF(('2回目フォームの回答 '!BF5="不満足"),4,""))))))) -> 1 | CM5: =IF(('2回目フォームの回答 '!BG5="満足"),1,(IF(('2回目フォームの回答 '!BG5="まぁ満足"),2,(IF(('2回目フォームの回答 '!BG5="やや満足"),3,(IF(('2回目フォームの回答 '!BG5="不満足"),4,""))))))) -> 3 | CN5: =15-($CC5+$CF5+$CI5) -> 9 | CO5: =IF(AND(B5="male",CN5<=4),5,(IF(AND(B5="male",CN5>=5,CN5<=6),4,(IF(AND(B5="male",CN5>=7,CN5<=8),3,(IF(AND(B5="male",CN5>=9,CN5<=10),2,IF(AND(B5="male",CN5>=11),1,IF(AND(B5="female",CN5<=3),5,(IF(AND(B5="female",CN5>=4,CN5<=5),4,(IF(AND(B5="female",CN5>=6,CN5<=7),3,(IF(AND(B5="female",CN5>=8,CN5<=10),2,IF(AND(B5="female",CN5>=11),1,"")))))))))))))))) -> 2 | CP5: =15-($CD5+$CG5+$CJ5) -> 9 | CQ5: =IF((CP5<=5),5,(IF(AND(CP5>=6,CP5<=7),4,(IF(AND(CP5>=8,CP5<=9),3,(IF(AND(CP5>=10,AF5<=11),2,IF(AF5>=12,1,"")))))))) -> 3 | CR5: =15-($CE5+$CH5+$CK5) -> 9 | CS5: =IF((CR5<=6),5,(IF(AND(CR5>=7,CR5<=8),4,IF((CR5=9),3,IF(AND(CR5>=10,CR5<=11),2,IF(CR5>=12,1,"")))))) -> 3 | CT5: =10-($CL5+$CM5) -> 6 | CU5: =IF((CT5<=3),5,(IF((CT5=4),4,IF(AND(CT5>=5,CT5<=6),3,IF((CT5=7),2,IF(CT5>=8,1,"")))))) -> 3 | CV5: =BR5+BT5+BV5+BX5+BZ5+CB5 -> 14 | CW5: =W5+Y5+AA5+AC5+AE5+AG5+AI5+AK5+AM5 -> 19 | CX5: =CO5+CQ5+CS5 -> 8 | CY5: =IF((CV5>=24),"高",IF(AND(CV5>=19,CV5<=23,(CW5+CX5)>=46),"高",IF(AND(CV5>=19,CV5<=23,(CW5+CX5)>=12,(CW5+CX5)<=45),"中①",IF(AND(CV5>=6,CV5<=18,(CW5+CX5)>=46),"中②","低")))) -> 低 | CZ5: ='2回目フォームの回答 '!BH5 -> 0.9 | DA5: =1-CZ5 -> 0.1 | DB5: =IF(('2回目フォームの回答 '!BI5="いつもより寝つきは良い"),0,(IF(('2回目フォームの回答 '!BI5="いつもより少し時間がかかった"),1,(IF(('2回目フォームの回答 '!BI5="いつもよりかなり時間がかかった"),2,(IF(('2回目フォームの回答 '!BI5="いつもより非常に時間がかかった、あるいは全く眠れなかった"),3,""))))))) -> 1 | DC5: =IF(('2回目フォームの回答 '!BJ5="問題になるほどのことはなかった"),0,(IF(('2回目フォームの回答 '!BJ5="少し困ることがある"),1,(IF(('2回目フォームの回答 '!BJ5="かなり困っている"),2,(IF(('2回目フォームの回答 '!BJ5="深刻な状態、あるいは全く眠れなかった"),3,""))))))) -> 0 | DD5: =IF(('2回目フォームの回答 '!BK5="そのようなことはなかった"),0,(IF(('2回目フォームの回答 '!BK5="少し早かった"),1,(IF(('2回目フォームの回答 '!BK5="かなり早かった"),2,(IF(('2回目フォームの回答 '!BK5="非常に早かった、あるいは全く眠れなかった"),3,""))))))) -> 1 | DE5: =IF(('2回目フォームの回答 '!BL5="十分である"),0,(IF(('2回目フォームの回答 '!BL5="少し足りない"),1,(IF(('2回目フォームの回答 '!BL5="かなり足りない"),2,(IF(('2回目フォームの回答 '!BL5="全く足りない、あるいは全く眠れなかった"),3,""))))))) -> 1 | DF5: =IF(('2回目フォームの回答 '!BM5="満足している"),0,(IF(('2回目フォームの回答 '!BM5="少し不満である"),1,(IF(('2回目フォームの回答 '!BM5="かなり不満である"),2,(IF(('2回目フォームの回答 '!BM5="非常に不満である、あるいは全く眠れなかった"),3,""))))))) -> 1 | DG5: =IF(('2回目フォームの回答 '!BN5="いつもどおり"),0,(IF(('2回目フォームの回答 '!BN5="少し滅入った"),1,(IF(('2回目フォームの回答 '!BN5="かなり滅入った"),2,(IF(('2回目フォームの回答 '!BN5="非常に滅入った"),3,""))))))) -> 0 | DH5: =IF(('2回目フォームの回答 '!BO5="いつもどおり"),0,(IF(('2回目フォームの回答 '!BO5="少し低下した"),1,(IF(('2回目フォームの回答 '!BO5="かなり低下した"),2,(IF(('2回目フォームの回答 '!BO5="非常に低下した"),3,""))))))) -> 0 | DI5: =IF(('2回目フォームの回答 '!BP5="全くなかった"),0,(IF(('2回目フォームの回答 '!BP5="少しあった"),1,(IF(('2回目フォームの回答 '!BP5="かなりあった"),2,(IF(('2回目フォームの回答 '!BP5="激しかった"),3,""))))))) -> 1 | DJ5: =SUM(DB5:DI5) -> 5 | DK5: =IF((DJ5<=3),"低",(IF(AND(DJ5>=4,DJ5<=5),"中",(IF((DJ5>=6),"高",""))))) -> 中 | DL5: 9.5 | DM5: 9.2 | DN5: 9.6 | DO5: =DL5+DM5+DN5 -> 28.3 | DQ5: 〇 | DT5: #N/A | DU5: =INDEX('1回目結果'!DR:DR,MATCH($DT5,'1回目結果'!$A:$A,0)) -> #N/A | DV5: =INDEX('1回目結果'!DS:DS,MATCH($DT5,'1回目結果'!$A:$A,0)) -> #N/A | DW5: =INDEX('1回目結果'!DT:DT,MATCH($DT5,'1回目結果'!$A:$A,0)) -> #N/A | DX5: =INDEX('1回目結果'!DU:DU,MATCH($DT5,'1回目結果'!$A:$A,0)) -> #N/A | DY5: =IFERROR(INDEX('1回目結果'!DL:DL,MATCH('2回目結果'!$DT5,'1回目結果'!$A:$A,0)),"") | DZ5: =IFERROR(INDEX('1回目結果'!DM:DM,MATCH('2回目結果'!$DT5,'1回目結果'!$A:$A,0)),"") | EA5: =IFERROR(INDEX('1回目結果'!DN:DN,MATCH('2回目結果'!$DT5,'1回目結果'!$A:$A,0)),"") | EB5: =IFERROR(INDEX('1回目結果'!DO:DO,MATCH('2回目結果'!$DT5,'1回目結果'!$A:$A,0)),"") | EC5: =IFERROR(INDEX('1回目結果'!DP:DP,MATCH('2回目結果'!$DT5,'1回目結果'!$A:$A,0)),"") | ED5: =IFERROR(INDEX('1回目結果'!DQ:DQ,MATCH('2回目結果'!$DT5,'1回目結果'!$A:$A,0)),"") | EE5: 2.028 | EF5: 204.98 | EG5: 0.99 | EH5: 50 | EI5: メンタルアラートなし（-） | EJ5: =EH5/DX5 -> #N/A | EK5: =EG5/DW5 -> #N/A | EL5: =DO5-EB5 -> #VALUE! | EM5: =DN5-EA5 -> #VALUE!
